[W 20181220 06:41:01 base:152] Not Found: /api/captcha/
[W 20181220 06:41:01 basehttp:124] "GET /api/captcha/ HTTP/1.1" 404 4363
[W 20181220 06:41:39 basehttp:124] "GET /api/v1/captcha/ HTTP/1.1" 405 45
[E 20181220 06:41:45 exception:135] Internal Server Error: /api/v1/captcha/
Traceback (most recent call last):
  File "/Users/yi/.virtualenvs/yi3/lib/python3.6/site-packages/django/core/handlers/exception.py", line 41, in inner
    response = get_response(request)
  File "/Users/yi/.virtualenvs/yi3/lib/python3.6/site-packages/django/core/handlers/base.py", line 187, in _get_response
    response = self.process_exception_by_middleware(e, request)
  File "/Users/yi/.virtualenvs/yi3/lib/python3.6/site-packages/django/core/handlers/base.py", line 185, in _get_response
    response = wrapped_callback(request, *callback_args, **callback_kwargs)
  File "/Users/yi/.virtualenvs/yi3/lib/python3.6/site-packages/django/views/decorators/csrf.py", line 58, in wrapped_view
    return view_func(*args, **kwargs)
  File "/Users/yi/.virtualenvs/yi3/lib/python3.6/site-packages/django/views/generic/base.py", line 68, in view
    return self.dispatch(request, *args, **kwargs)
  File "/Users/yi/.virtualenvs/yi3/lib/python3.6/site-packages/rest_framework/views.py", line 483, in dispatch
    response = self.handle_exception(exc)
  File "/Users/yi/.virtualenvs/yi3/lib/python3.6/site-packages/rest_framework/views.py", line 443, in handle_exception
    self.raise_uncaught_exception(exc)
  File "/Users/yi/.virtualenvs/yi3/lib/python3.6/site-packages/rest_framework/views.py", line 480, in dispatch
    response = handler(request, *args, **kwargs)
  File "/Users/yi/PycharmProjects/djangos/web_chat/chat/api_views/account.py", line 73, in post
    email = request.data['email']
KeyError: 'email'
[E 20181220 06:41:45 basehttp:124] "POST /api/v1/captcha/ HTTP/1.1" 500 15201
[E 20181220 06:42:08 exception:135] Internal Server Error: /api/v1/captcha/
Traceback (most recent call last):
  File "/Users/yi/.virtualenvs/yi3/lib/python3.6/site-packages/django/core/handlers/exception.py", line 41, in inner
    response = get_response(request)
  File "/Users/yi/.virtualenvs/yi3/lib/python3.6/site-packages/django/core/handlers/base.py", line 187, in _get_response
    response = self.process_exception_by_middleware(e, request)
  File "/Users/yi/.virtualenvs/yi3/lib/python3.6/site-packages/django/core/handlers/base.py", line 185, in _get_response
    response = wrapped_callback(request, *callback_args, **callback_kwargs)
  File "/Users/yi/.virtualenvs/yi3/lib/python3.6/site-packages/django/views/decorators/csrf.py", line 58, in wrapped_view
    return view_func(*args, **kwargs)
  File "/Users/yi/.virtualenvs/yi3/lib/python3.6/site-packages/django/views/generic/base.py", line 68, in view
    return self.dispatch(request, *args, **kwargs)
  File "/Users/yi/.virtualenvs/yi3/lib/python3.6/site-packages/rest_framework/views.py", line 483, in dispatch
    response = self.handle_exception(exc)
  File "/Users/yi/.virtualenvs/yi3/lib/python3.6/site-packages/rest_framework/views.py", line 443, in handle_exception
    self.raise_uncaught_exception(exc)
  File "/Users/yi/.virtualenvs/yi3/lib/python3.6/site-packages/rest_framework/views.py", line 480, in dispatch
    response = handler(request, *args, **kwargs)
  File "/Users/yi/PycharmProjects/djangos/web_chat/chat/api_views/account.py", line 73, in post
    email = request.data['email']
KeyError: 'email'
[E 20181220 06:42:08 basehttp:124] "POST /api/v1/captcha/?email=973697101@qq.com HTTP/1.1" 500 15261
[E 20181220 06:44:00 exception:135] Internal Server Error: /api/v1/captcha/
Traceback (most recent call last):
  File "/Users/yi/.virtualenvs/yi3/lib/python3.6/site-packages/django/core/handlers/exception.py", line 41, in inner
    response = get_response(request)
  File "/Users/yi/.virtualenvs/yi3/lib/python3.6/site-packages/django/core/handlers/base.py", line 187, in _get_response
    response = self.process_exception_by_middleware(e, request)
  File "/Users/yi/.virtualenvs/yi3/lib/python3.6/site-packages/django/core/handlers/base.py", line 185, in _get_response
    response = wrapped_callback(request, *callback_args, **callback_kwargs)
  File "/Users/yi/.virtualenvs/yi3/lib/python3.6/site-packages/django/views/decorators/csrf.py", line 58, in wrapped_view
    return view_func(*args, **kwargs)
  File "/Users/yi/.virtualenvs/yi3/lib/python3.6/site-packages/django/views/generic/base.py", line 68, in view
    return self.dispatch(request, *args, **kwargs)
  File "/Users/yi/.virtualenvs/yi3/lib/python3.6/site-packages/rest_framework/views.py", line 483, in dispatch
    response = self.handle_exception(exc)
  File "/Users/yi/.virtualenvs/yi3/lib/python3.6/site-packages/rest_framework/views.py", line 443, in handle_exception
    self.raise_uncaught_exception(exc)
  File "/Users/yi/.virtualenvs/yi3/lib/python3.6/site-packages/rest_framework/views.py", line 480, in dispatch
    response = handler(request, *args, **kwargs)
  File "/Users/yi/PycharmProjects/djangos/web_chat/chat/api_views/account.py", line 76, in post
    email_helper.send_captcha(receive_email=email)
  File "/Users/yi/PycharmProjects/djangos/web_chat/util/email.py", line 23, in send_captcha
    status = send_mail(email_title, email_body, self.email_from, [receive_email, ])
  File "/Users/yi/.virtualenvs/yi3/lib/python3.6/site-packages/django/core/mail/__init__.py", line 62, in send_mail
    return mail.send()
  File "/Users/yi/.virtualenvs/yi3/lib/python3.6/site-packages/django/core/mail/message.py", line 348, in send
    return self.get_connection(fail_silently).send_messages([self])
  File "/Users/yi/.virtualenvs/yi3/lib/python3.6/site-packages/django/core/mail/backends/smtp.py", line 104, in send_messages
    new_conn_created = self.open()
  File "/Users/yi/.virtualenvs/yi3/lib/python3.6/site-packages/django/core/mail/backends/smtp.py", line 71, in open
    self.connection.login(force_str(self.username), force_str(self.password))
  File "/usr/local/Cellar/python/3.6.5/Frameworks/Python.framework/Versions/3.6/lib/python3.6/smtplib.py", line 730, in login
    raise last_exception
  File "/usr/local/Cellar/python/3.6.5/Frameworks/Python.framework/Versions/3.6/lib/python3.6/smtplib.py", line 721, in login
    initial_response_ok=initial_response_ok)
  File "/usr/local/Cellar/python/3.6.5/Frameworks/Python.framework/Versions/3.6/lib/python3.6/smtplib.py", line 642, in auth
    raise SMTPAuthenticationError(code, resp)
smtplib.SMTPAuthenticationError: (535, b'Error: authentication failed')
[E 20181220 06:44:00 basehttp:124] "POST /api/v1/captcha/ HTTP/1.1" 500 16702
[E 20181220 06:48:15 exception:135] Internal Server Error: /api/v1/captcha/
Traceback (most recent call last):
  File "/Users/yi/.virtualenvs/yi3/lib/python3.6/site-packages/django/core/handlers/exception.py", line 41, in inner
    response = get_response(request)
  File "/Users/yi/.virtualenvs/yi3/lib/python3.6/site-packages/django/core/handlers/base.py", line 187, in _get_response
    response = self.process_exception_by_middleware(e, request)
  File "/Users/yi/.virtualenvs/yi3/lib/python3.6/site-packages/django/core/handlers/base.py", line 185, in _get_response
    response = wrapped_callback(request, *callback_args, **callback_kwargs)
  File "/Users/yi/.virtualenvs/yi3/lib/python3.6/site-packages/django/views/decorators/csrf.py", line 58, in wrapped_view
    return view_func(*args, **kwargs)
  File "/Users/yi/.virtualenvs/yi3/lib/python3.6/site-packages/django/views/generic/base.py", line 68, in view
    return self.dispatch(request, *args, **kwargs)
  File "/Users/yi/.virtualenvs/yi3/lib/python3.6/site-packages/rest_framework/views.py", line 483, in dispatch
    response = self.handle_exception(exc)
  File "/Users/yi/.virtualenvs/yi3/lib/python3.6/site-packages/rest_framework/views.py", line 443, in handle_exception
    self.raise_uncaught_exception(exc)
  File "/Users/yi/.virtualenvs/yi3/lib/python3.6/site-packages/rest_framework/views.py", line 480, in dispatch
    response = handler(request, *args, **kwargs)
  File "/Users/yi/PycharmProjects/djangos/web_chat/chat/api_views/account.py", line 74, in post
    email_helper.send_captcha(receive_email=email)
  File "/Users/yi/PycharmProjects/djangos/web_chat/util/email.py", line 23, in send_captcha
    status = send_mail(email_title, email_body, self.email_from, [receive_email, ])
  File "/Users/yi/.virtualenvs/yi3/lib/python3.6/site-packages/django/core/mail/__init__.py", line 62, in send_mail
    return mail.send()
  File "/Users/yi/.virtualenvs/yi3/lib/python3.6/site-packages/django/core/mail/message.py", line 348, in send
    return self.get_connection(fail_silently).send_messages([self])
  File "/Users/yi/.virtualenvs/yi3/lib/python3.6/site-packages/django/core/mail/backends/smtp.py", line 104, in send_messages
    new_conn_created = self.open()
  File "/Users/yi/.virtualenvs/yi3/lib/python3.6/site-packages/django/core/mail/backends/smtp.py", line 71, in open
    self.connection.login(force_str(self.username), force_str(self.password))
  File "/usr/local/Cellar/python/3.6.5/Frameworks/Python.framework/Versions/3.6/lib/python3.6/smtplib.py", line 730, in login
    raise last_exception
  File "/usr/local/Cellar/python/3.6.5/Frameworks/Python.framework/Versions/3.6/lib/python3.6/smtplib.py", line 721, in login
    initial_response_ok=initial_response_ok)
  File "/usr/local/Cellar/python/3.6.5/Frameworks/Python.framework/Versions/3.6/lib/python3.6/smtplib.py", line 642, in auth
    raise SMTPAuthenticationError(code, resp)
smtplib.SMTPAuthenticationError: (535, b'Error: authentication failed')
[E 20181220 06:48:15 basehttp:124] "POST /api/v1/captcha/ HTTP/1.1" 500 16702
[E 20181220 06:52:08 exception:135] Internal Server Error: /api/v1/captcha/
Traceback (most recent call last):
  File "/Users/yi/.virtualenvs/yi3/lib/python3.6/site-packages/django/core/handlers/exception.py", line 41, in inner
    response = get_response(request)
  File "/Users/yi/.virtualenvs/yi3/lib/python3.6/site-packages/django/core/handlers/base.py", line 187, in _get_response
    response = self.process_exception_by_middleware(e, request)
  File "/Users/yi/.virtualenvs/yi3/lib/python3.6/site-packages/django/core/handlers/base.py", line 185, in _get_response
    response = wrapped_callback(request, *callback_args, **callback_kwargs)
  File "/Users/yi/.virtualenvs/yi3/lib/python3.6/site-packages/django/views/decorators/csrf.py", line 58, in wrapped_view
    return view_func(*args, **kwargs)
  File "/Users/yi/.virtualenvs/yi3/lib/python3.6/site-packages/django/views/generic/base.py", line 68, in view
    return self.dispatch(request, *args, **kwargs)
  File "/Users/yi/.virtualenvs/yi3/lib/python3.6/site-packages/rest_framework/views.py", line 483, in dispatch
    response = self.handle_exception(exc)
  File "/Users/yi/.virtualenvs/yi3/lib/python3.6/site-packages/rest_framework/views.py", line 443, in handle_exception
    self.raise_uncaught_exception(exc)
  File "/Users/yi/.virtualenvs/yi3/lib/python3.6/site-packages/rest_framework/views.py", line 480, in dispatch
    response = handler(request, *args, **kwargs)
  File "/Users/yi/PycharmProjects/djangos/web_chat/chat/api_views/account.py", line 74, in post
    email_helper.send_captcha(receive_email=email)
  File "/Users/yi/PycharmProjects/djangos/web_chat/util/email.py", line 23, in send_captcha
    status = send_mail(email_title, email_body, self.email_from, [receive_email, ])
  File "/Users/yi/.virtualenvs/yi3/lib/python3.6/site-packages/django/core/mail/__init__.py", line 62, in send_mail
    return mail.send()
  File "/Users/yi/.virtualenvs/yi3/lib/python3.6/site-packages/django/core/mail/message.py", line 348, in send
    return self.get_connection(fail_silently).send_messages([self])
  File "/Users/yi/.virtualenvs/yi3/lib/python3.6/site-packages/django/core/mail/backends/smtp.py", line 104, in send_messages
    new_conn_created = self.open()
  File "/Users/yi/.virtualenvs/yi3/lib/python3.6/site-packages/django/core/mail/backends/smtp.py", line 71, in open
    self.connection.login(force_str(self.username), force_str(self.password))
  File "/usr/local/Cellar/python/3.6.5/Frameworks/Python.framework/Versions/3.6/lib/python3.6/smtplib.py", line 730, in login
    raise last_exception
  File "/usr/local/Cellar/python/3.6.5/Frameworks/Python.framework/Versions/3.6/lib/python3.6/smtplib.py", line 721, in login
    initial_response_ok=initial_response_ok)
  File "/usr/local/Cellar/python/3.6.5/Frameworks/Python.framework/Versions/3.6/lib/python3.6/smtplib.py", line 642, in auth
    raise SMTPAuthenticationError(code, resp)
smtplib.SMTPAuthenticationError: (535, b'Error: authentication failed')
[E 20181220 06:52:08 basehttp:124] "POST /api/v1/captcha/ HTTP/1.1" 500 16701
[E 20181220 06:53:11 exception:135] Internal Server Error: /api/v1/captcha/
Traceback (most recent call last):
  File "/Users/yi/.virtualenvs/yi3/lib/python3.6/site-packages/django/core/handlers/exception.py", line 41, in inner
    response = get_response(request)
  File "/Users/yi/.virtualenvs/yi3/lib/python3.6/site-packages/django/core/handlers/base.py", line 187, in _get_response
    response = self.process_exception_by_middleware(e, request)
  File "/Users/yi/.virtualenvs/yi3/lib/python3.6/site-packages/django/core/handlers/base.py", line 185, in _get_response
    response = wrapped_callback(request, *callback_args, **callback_kwargs)
  File "/Users/yi/.virtualenvs/yi3/lib/python3.6/site-packages/django/views/decorators/csrf.py", line 58, in wrapped_view
    return view_func(*args, **kwargs)
  File "/Users/yi/.virtualenvs/yi3/lib/python3.6/site-packages/django/views/generic/base.py", line 68, in view
    return self.dispatch(request, *args, **kwargs)
  File "/Users/yi/.virtualenvs/yi3/lib/python3.6/site-packages/rest_framework/views.py", line 483, in dispatch
    response = self.handle_exception(exc)
  File "/Users/yi/.virtualenvs/yi3/lib/python3.6/site-packages/rest_framework/views.py", line 443, in handle_exception
    self.raise_uncaught_exception(exc)
  File "/Users/yi/.virtualenvs/yi3/lib/python3.6/site-packages/rest_framework/views.py", line 480, in dispatch
    response = handler(request, *args, **kwargs)
  File "/Users/yi/PycharmProjects/djangos/web_chat/chat/api_views/account.py", line 74, in post
    email_helper.send_captcha(receive_email=email)
  File "/Users/yi/PycharmProjects/djangos/web_chat/util/email.py", line 23, in send_captcha
    status = send_mail(email_title, email_body, self.email_from, [receive_email, ])
  File "/Users/yi/.virtualenvs/yi3/lib/python3.6/site-packages/django/core/mail/__init__.py", line 62, in send_mail
    return mail.send()
  File "/Users/yi/.virtualenvs/yi3/lib/python3.6/site-packages/django/core/mail/message.py", line 348, in send
    return self.get_connection(fail_silently).send_messages([self])
  File "/Users/yi/.virtualenvs/yi3/lib/python3.6/site-packages/django/core/mail/backends/smtp.py", line 111, in send_messages
    sent = self._send(message)
  File "/Users/yi/.virtualenvs/yi3/lib/python3.6/site-packages/django/core/mail/backends/smtp.py", line 127, in _send
    self.connection.sendmail(from_email, recipients, message.as_bytes(linesep='\r\n'))
  File "/usr/local/Cellar/python/3.6.5/Frameworks/Python.framework/Versions/3.6/lib/python3.6/smtplib.py", line 867, in sendmail
    raise SMTPSenderRefused(code, resp, from_addr)
smtplib.SMTPSenderRefused: (553, b'Mail from must equal authorized user', 'jdecree@sina.com')
[E 20181220 06:53:11 basehttp:124] "POST /api/v1/captcha/ HTTP/1.1" 500 16434
[E 20181220 06:55:05 exception:135] Internal Server Error: /api/v1/captcha/
Traceback (most recent call last):
  File "/Users/yi/.virtualenvs/yi3/lib/python3.6/site-packages/django/core/handlers/exception.py", line 41, in inner
    response = get_response(request)
  File "/Users/yi/.virtualenvs/yi3/lib/python3.6/site-packages/django/core/handlers/base.py", line 187, in _get_response
    response = self.process_exception_by_middleware(e, request)
  File "/Users/yi/.virtualenvs/yi3/lib/python3.6/site-packages/django/core/handlers/base.py", line 185, in _get_response
    response = wrapped_callback(request, *callback_args, **callback_kwargs)
  File "/Users/yi/.virtualenvs/yi3/lib/python3.6/site-packages/django/views/decorators/csrf.py", line 58, in wrapped_view
    return view_func(*args, **kwargs)
  File "/Users/yi/.virtualenvs/yi3/lib/python3.6/site-packages/django/views/generic/base.py", line 68, in view
    return self.dispatch(request, *args, **kwargs)
  File "/Users/yi/.virtualenvs/yi3/lib/python3.6/site-packages/rest_framework/views.py", line 483, in dispatch
    response = self.handle_exception(exc)
  File "/Users/yi/.virtualenvs/yi3/lib/python3.6/site-packages/rest_framework/views.py", line 443, in handle_exception
    self.raise_uncaught_exception(exc)
  File "/Users/yi/.virtualenvs/yi3/lib/python3.6/site-packages/rest_framework/views.py", line 480, in dispatch
    response = handler(request, *args, **kwargs)
  File "/Users/yi/PycharmProjects/djangos/web_chat/chat/api_views/account.py", line 74, in post
    email_helper.send_captcha(receive_email=email)
  File "/Users/yi/PycharmProjects/djangos/web_chat/util/email.py", line 23, in send_captcha
    status = send_mail(email_title, email_body, self.email_from, [receive_email, ])
  File "/Users/yi/.virtualenvs/yi3/lib/python3.6/site-packages/django/core/mail/__init__.py", line 62, in send_mail
    return mail.send()
  File "/Users/yi/.virtualenvs/yi3/lib/python3.6/site-packages/django/core/mail/message.py", line 348, in send
    return self.get_connection(fail_silently).send_messages([self])
  File "/Users/yi/.virtualenvs/yi3/lib/python3.6/site-packages/django/core/mail/backends/smtp.py", line 111, in send_messages
    sent = self._send(message)
  File "/Users/yi/.virtualenvs/yi3/lib/python3.6/site-packages/django/core/mail/backends/smtp.py", line 127, in _send
    self.connection.sendmail(from_email, recipients, message.as_bytes(linesep='\r\n'))
  File "/usr/local/Cellar/python/3.6.5/Frameworks/Python.framework/Versions/3.6/lib/python3.6/smtplib.py", line 888, in sendmail
    raise SMTPDataError(code, resp)
smtplib.SMTPDataError: (554, b'DT:SPM 163 smtp14,EsCowADnNobJPBtcNWX2Fw--.7302S2 1545288905,please see http://mail.163.com/help/help_spam_16.htm?ip=59.42.191.95&hostid=smtp14&time=1545288905')
[E 20181220 06:55:05 basehttp:124] "POST /api/v1/captcha/ HTTP/1.1" 500 16616
[E 20181220 06:57:41 exception:135] Internal Server Error: /api/v1/captcha/
Traceback (most recent call last):
  File "/Users/yi/.virtualenvs/yi3/lib/python3.6/site-packages/django/core/handlers/exception.py", line 41, in inner
    response = get_response(request)
  File "/Users/yi/.virtualenvs/yi3/lib/python3.6/site-packages/django/core/handlers/base.py", line 187, in _get_response
    response = self.process_exception_by_middleware(e, request)
  File "/Users/yi/.virtualenvs/yi3/lib/python3.6/site-packages/django/core/handlers/base.py", line 185, in _get_response
    response = wrapped_callback(request, *callback_args, **callback_kwargs)
  File "/Users/yi/.virtualenvs/yi3/lib/python3.6/site-packages/django/views/decorators/csrf.py", line 58, in wrapped_view
    return view_func(*args, **kwargs)
  File "/Users/yi/.virtualenvs/yi3/lib/python3.6/site-packages/django/views/generic/base.py", line 68, in view
    return self.dispatch(request, *args, **kwargs)
  File "/Users/yi/.virtualenvs/yi3/lib/python3.6/site-packages/rest_framework/views.py", line 483, in dispatch
    response = self.handle_exception(exc)
  File "/Users/yi/.virtualenvs/yi3/lib/python3.6/site-packages/rest_framework/views.py", line 443, in handle_exception
    self.raise_uncaught_exception(exc)
  File "/Users/yi/.virtualenvs/yi3/lib/python3.6/site-packages/rest_framework/views.py", line 480, in dispatch
    response = handler(request, *args, **kwargs)
  File "/Users/yi/PycharmProjects/djangos/web_chat/chat/api_views/account.py", line 74, in post
    email_helper.send_captcha(receive_email=email)
  File "/Users/yi/PycharmProjects/djangos/web_chat/util/email.py", line 23, in send_captcha
    status = send_mail(email_title, email_body, self.email_from, [receive_email, ])
  File "/Users/yi/.virtualenvs/yi3/lib/python3.6/site-packages/django/core/mail/__init__.py", line 62, in send_mail
    return mail.send()
  File "/Users/yi/.virtualenvs/yi3/lib/python3.6/site-packages/django/core/mail/message.py", line 348, in send
    return self.get_connection(fail_silently).send_messages([self])
  File "/Users/yi/.virtualenvs/yi3/lib/python3.6/site-packages/django/core/mail/backends/smtp.py", line 111, in send_messages
    sent = self._send(message)
  File "/Users/yi/.virtualenvs/yi3/lib/python3.6/site-packages/django/core/mail/backends/smtp.py", line 127, in _send
    self.connection.sendmail(from_email, recipients, message.as_bytes(linesep='\r\n'))
  File "/usr/local/Cellar/python/3.6.5/Frameworks/Python.framework/Versions/3.6/lib/python3.6/smtplib.py", line 888, in sendmail
    raise SMTPDataError(code, resp)
smtplib.SMTPDataError: (554, b'DT:SPM 163 smtp12,EMCowABHhTxlPRtc1lsaEA--.7585S2 1545289061,please see http://mail.163.com/help/help_spam_16.htm?ip=59.42.191.95&hostid=smtp12&time=1545289061')
[E 20181220 06:57:41 basehttp:124] "POST /api/v1/captcha/ HTTP/1.1" 500 16616
[E 20181220 07:04:26 exception:135] Internal Server Error: /api/v1/captcha/
Traceback (most recent call last):
  File "/Users/yi/.virtualenvs/yi3/lib/python3.6/site-packages/django/core/handlers/exception.py", line 41, in inner
    response = get_response(request)
  File "/Users/yi/.virtualenvs/yi3/lib/python3.6/site-packages/django/core/handlers/base.py", line 187, in _get_response
    response = self.process_exception_by_middleware(e, request)
  File "/Users/yi/.virtualenvs/yi3/lib/python3.6/site-packages/django/core/handlers/base.py", line 185, in _get_response
    response = wrapped_callback(request, *callback_args, **callback_kwargs)
  File "/Users/yi/.virtualenvs/yi3/lib/python3.6/site-packages/django/views/decorators/csrf.py", line 58, in wrapped_view
    return view_func(*args, **kwargs)
  File "/Users/yi/.virtualenvs/yi3/lib/python3.6/site-packages/django/views/generic/base.py", line 68, in view
    return self.dispatch(request, *args, **kwargs)
  File "/Users/yi/.virtualenvs/yi3/lib/python3.6/site-packages/rest_framework/views.py", line 483, in dispatch
    response = self.handle_exception(exc)
  File "/Users/yi/.virtualenvs/yi3/lib/python3.6/site-packages/rest_framework/views.py", line 443, in handle_exception
    self.raise_uncaught_exception(exc)
  File "/Users/yi/.virtualenvs/yi3/lib/python3.6/site-packages/rest_framework/views.py", line 480, in dispatch
    response = handler(request, *args, **kwargs)
  File "/Users/yi/PycharmProjects/djangos/web_chat/chat/api_views/account.py", line 74, in post
    email_helper.send_captcha(receive_email=email)
  File "/Users/yi/PycharmProjects/djangos/web_chat/util/email.py", line 23, in send_captcha
    status = send_mail(email_title, email_body, self.email_from, [receive_email, ])
  File "/Users/yi/.virtualenvs/yi3/lib/python3.6/site-packages/django/core/mail/__init__.py", line 62, in send_mail
    return mail.send()
  File "/Users/yi/.virtualenvs/yi3/lib/python3.6/site-packages/django/core/mail/message.py", line 348, in send
    return self.get_connection(fail_silently).send_messages([self])
  File "/Users/yi/.virtualenvs/yi3/lib/python3.6/site-packages/django/core/mail/backends/smtp.py", line 111, in send_messages
    sent = self._send(message)
  File "/Users/yi/.virtualenvs/yi3/lib/python3.6/site-packages/django/core/mail/backends/smtp.py", line 127, in _send
    self.connection.sendmail(from_email, recipients, message.as_bytes(linesep='\r\n'))
  File "/usr/local/Cellar/python/3.6.5/Frameworks/Python.framework/Versions/3.6/lib/python3.6/smtplib.py", line 888, in sendmail
    raise SMTPDataError(code, resp)
smtplib.SMTPDataError: (554, b'DT:SPM 163 smtp8,DMCowAAHbXb6PhtcozQ_GQ--.2470S2 1545289466,please see http://mail.163.com/help/help_spam_16.htm?ip=59.42.191.95&hostid=smtp8&time=1545289466')
[E 20181220 07:04:26 basehttp:124] "POST /api/v1/captcha/ HTTP/1.1" 500 16612
[E 20181220 07:06:16 exception:135] Internal Server Error: /api/v1/captcha/
Traceback (most recent call last):
  File "/Users/yi/.virtualenvs/yi3/lib/python3.6/site-packages/django/core/handlers/exception.py", line 41, in inner
    response = get_response(request)
  File "/Users/yi/.virtualenvs/yi3/lib/python3.6/site-packages/django/core/handlers/base.py", line 187, in _get_response
    response = self.process_exception_by_middleware(e, request)
  File "/Users/yi/.virtualenvs/yi3/lib/python3.6/site-packages/django/core/handlers/base.py", line 185, in _get_response
    response = wrapped_callback(request, *callback_args, **callback_kwargs)
  File "/Users/yi/.virtualenvs/yi3/lib/python3.6/site-packages/django/views/decorators/csrf.py", line 58, in wrapped_view
    return view_func(*args, **kwargs)
  File "/Users/yi/.virtualenvs/yi3/lib/python3.6/site-packages/django/views/generic/base.py", line 68, in view
    return self.dispatch(request, *args, **kwargs)
  File "/Users/yi/.virtualenvs/yi3/lib/python3.6/site-packages/rest_framework/views.py", line 483, in dispatch
    response = self.handle_exception(exc)
  File "/Users/yi/.virtualenvs/yi3/lib/python3.6/site-packages/rest_framework/views.py", line 443, in handle_exception
    self.raise_uncaught_exception(exc)
  File "/Users/yi/.virtualenvs/yi3/lib/python3.6/site-packages/rest_framework/views.py", line 480, in dispatch
    response = handler(request, *args, **kwargs)
  File "/Users/yi/PycharmProjects/djangos/web_chat/chat/api_views/account.py", line 74, in post
    email_helper.send_captcha(receive_email=email)
  File "/Users/yi/PycharmProjects/djangos/web_chat/util/email.py", line 23, in send_captcha
    status = send_mail(email_title, email_body, self.email_from, [receive_email, ])
  File "/Users/yi/.virtualenvs/yi3/lib/python3.6/site-packages/django/core/mail/__init__.py", line 62, in send_mail
    return mail.send()
  File "/Users/yi/.virtualenvs/yi3/lib/python3.6/site-packages/django/core/mail/message.py", line 348, in send
    return self.get_connection(fail_silently).send_messages([self])
  File "/Users/yi/.virtualenvs/yi3/lib/python3.6/site-packages/django/core/mail/backends/smtp.py", line 111, in send_messages
    sent = self._send(message)
  File "/Users/yi/.virtualenvs/yi3/lib/python3.6/site-packages/django/core/mail/backends/smtp.py", line 127, in _send
    self.connection.sendmail(from_email, recipients, message.as_bytes(linesep='\r\n'))
  File "/usr/local/Cellar/python/3.6.5/Frameworks/Python.framework/Versions/3.6/lib/python3.6/smtplib.py", line 888, in sendmail
    raise SMTPDataError(code, resp)
smtplib.SMTPDataError: (554, b'DT:SPM 163 smtp13,EcCowADH4YRnPxtc4QMTAA--.1315S2 1545289576,please see http://mail.163.com/help/help_spam_16.htm?ip=59.42.191.95&hostid=smtp13&time=1545289576')
[E 20181220 07:06:16 basehttp:124] "POST /api/v1/captcha/ HTTP/1.1" 500 16616
[E 20181220 07:08:03 exception:135] Internal Server Error: /api/v1/captcha/
Traceback (most recent call last):
  File "/Users/yi/.virtualenvs/yi3/lib/python3.6/site-packages/django/core/handlers/exception.py", line 41, in inner
    response = get_response(request)
  File "/Users/yi/.virtualenvs/yi3/lib/python3.6/site-packages/django/core/handlers/base.py", line 187, in _get_response
    response = self.process_exception_by_middleware(e, request)
  File "/Users/yi/.virtualenvs/yi3/lib/python3.6/site-packages/django/core/handlers/base.py", line 185, in _get_response
    response = wrapped_callback(request, *callback_args, **callback_kwargs)
  File "/Users/yi/.virtualenvs/yi3/lib/python3.6/site-packages/django/views/decorators/csrf.py", line 58, in wrapped_view
    return view_func(*args, **kwargs)
  File "/Users/yi/.virtualenvs/yi3/lib/python3.6/site-packages/django/views/generic/base.py", line 68, in view
    return self.dispatch(request, *args, **kwargs)
  File "/Users/yi/.virtualenvs/yi3/lib/python3.6/site-packages/rest_framework/views.py", line 483, in dispatch
    response = self.handle_exception(exc)
  File "/Users/yi/.virtualenvs/yi3/lib/python3.6/site-packages/rest_framework/views.py", line 443, in handle_exception
    self.raise_uncaught_exception(exc)
  File "/Users/yi/.virtualenvs/yi3/lib/python3.6/site-packages/rest_framework/views.py", line 480, in dispatch
    response = handler(request, *args, **kwargs)
  File "/Users/yi/PycharmProjects/djangos/web_chat/chat/api_views/account.py", line 74, in post
    email_helper.send_captcha(receive_email=email)
  File "/Users/yi/PycharmProjects/djangos/web_chat/util/email.py", line 23, in send_captcha
    status = send_mail(email_title, email_body, self.email_from, [receive_email, ])
  File "/Users/yi/.virtualenvs/yi3/lib/python3.6/site-packages/django/core/mail/__init__.py", line 62, in send_mail
    return mail.send()
  File "/Users/yi/.virtualenvs/yi3/lib/python3.6/site-packages/django/core/mail/message.py", line 348, in send
    return self.get_connection(fail_silently).send_messages([self])
  File "/Users/yi/.virtualenvs/yi3/lib/python3.6/site-packages/django/core/mail/backends/smtp.py", line 111, in send_messages
    sent = self._send(message)
  File "/Users/yi/.virtualenvs/yi3/lib/python3.6/site-packages/django/core/mail/backends/smtp.py", line 127, in _send
    self.connection.sendmail(from_email, recipients, message.as_bytes(linesep='\r\n'))
  File "/usr/local/Cellar/python/3.6.5/Frameworks/Python.framework/Versions/3.6/lib/python3.6/smtplib.py", line 888, in sendmail
    raise SMTPDataError(code, resp)
smtplib.SMTPDataError: (554, b'DT:SPM 163 smtp8,DMCowADX60HTPxtcHaI_GQ--.58403S2 1545289683,please see http://mail.163.com/help/help_spam_16.htm?ip=59.42.191.95&hostid=smtp8&time=1545289683')
[E 20181220 07:08:03 basehttp:124] "POST /api/v1/captcha/ HTTP/1.1" 500 16615
[E 20181220 07:10:12 exception:135] Internal Server Error: /api/v1/captcha/
Traceback (most recent call last):
  File "/Users/yi/.virtualenvs/yi3/lib/python3.6/site-packages/django/core/handlers/exception.py", line 41, in inner
    response = get_response(request)
  File "/Users/yi/.virtualenvs/yi3/lib/python3.6/site-packages/django/core/handlers/base.py", line 187, in _get_response
    response = self.process_exception_by_middleware(e, request)
  File "/Users/yi/.virtualenvs/yi3/lib/python3.6/site-packages/django/core/handlers/base.py", line 185, in _get_response
    response = wrapped_callback(request, *callback_args, **callback_kwargs)
  File "/Users/yi/.virtualenvs/yi3/lib/python3.6/site-packages/django/views/decorators/csrf.py", line 58, in wrapped_view
    return view_func(*args, **kwargs)
  File "/Users/yi/.virtualenvs/yi3/lib/python3.6/site-packages/django/views/generic/base.py", line 68, in view
    return self.dispatch(request, *args, **kwargs)
  File "/Users/yi/.virtualenvs/yi3/lib/python3.6/site-packages/rest_framework/views.py", line 483, in dispatch
    response = self.handle_exception(exc)
  File "/Users/yi/.virtualenvs/yi3/lib/python3.6/site-packages/rest_framework/views.py", line 443, in handle_exception
    self.raise_uncaught_exception(exc)
  File "/Users/yi/.virtualenvs/yi3/lib/python3.6/site-packages/rest_framework/views.py", line 480, in dispatch
    response = handler(request, *args, **kwargs)
  File "/Users/yi/PycharmProjects/djangos/web_chat/chat/api_views/account.py", line 74, in post
    email_helper.send_captcha(receive_email=email)
  File "/Users/yi/PycharmProjects/djangos/web_chat/util/email.py", line 23, in send_captcha
    status = send_mail(email_title, email_body, self.email_from, [receive_email, ])
  File "/Users/yi/.virtualenvs/yi3/lib/python3.6/site-packages/django/core/mail/__init__.py", line 62, in send_mail
    return mail.send()
  File "/Users/yi/.virtualenvs/yi3/lib/python3.6/site-packages/django/core/mail/message.py", line 348, in send
    return self.get_connection(fail_silently).send_messages([self])
  File "/Users/yi/.virtualenvs/yi3/lib/python3.6/site-packages/django/core/mail/backends/smtp.py", line 111, in send_messages
    sent = self._send(message)
  File "/Users/yi/.virtualenvs/yi3/lib/python3.6/site-packages/django/core/mail/backends/smtp.py", line 127, in _send
    self.connection.sendmail(from_email, recipients, message.as_bytes(linesep='\r\n'))
  File "/usr/local/Cellar/python/3.6.5/Frameworks/Python.framework/Versions/3.6/lib/python3.6/smtplib.py", line 888, in sendmail
    raise SMTPDataError(code, resp)
smtplib.SMTPDataError: (554, b'DT:SPM 163 smtp13,EcCowAA3uBhUQBtc_VITAA--.4095S2 1545289812,please see http://mail.163.com/help/help_spam_16.htm?ip=59.42.191.95&hostid=smtp13&time=1545289812')
[E 20181220 07:10:12 basehttp:124] "POST /api/v1/captcha/ HTTP/1.1" 500 16617
[E 20181220 07:14:06 exception:135] Internal Server Error: /api/v1/captcha/
Traceback (most recent call last):
  File "/Users/yi/.virtualenvs/yi3/lib/python3.6/site-packages/django/core/handlers/exception.py", line 41, in inner
    response = get_response(request)
  File "/Users/yi/.virtualenvs/yi3/lib/python3.6/site-packages/django/core/handlers/base.py", line 187, in _get_response
    response = self.process_exception_by_middleware(e, request)
  File "/Users/yi/.virtualenvs/yi3/lib/python3.6/site-packages/django/core/handlers/base.py", line 185, in _get_response
    response = wrapped_callback(request, *callback_args, **callback_kwargs)
  File "/Users/yi/.virtualenvs/yi3/lib/python3.6/site-packages/django/views/decorators/csrf.py", line 58, in wrapped_view
    return view_func(*args, **kwargs)
  File "/Users/yi/.virtualenvs/yi3/lib/python3.6/site-packages/django/views/generic/base.py", line 68, in view
    return self.dispatch(request, *args, **kwargs)
  File "/Users/yi/.virtualenvs/yi3/lib/python3.6/site-packages/rest_framework/views.py", line 483, in dispatch
    response = self.handle_exception(exc)
  File "/Users/yi/.virtualenvs/yi3/lib/python3.6/site-packages/rest_framework/views.py", line 443, in handle_exception
    self.raise_uncaught_exception(exc)
  File "/Users/yi/.virtualenvs/yi3/lib/python3.6/site-packages/rest_framework/views.py", line 480, in dispatch
    response = handler(request, *args, **kwargs)
  File "/Users/yi/PycharmProjects/djangos/web_chat/chat/api_views/account.py", line 74, in post
    email_helper.send_captcha(receive_email=email)
  File "/Users/yi/PycharmProjects/djangos/web_chat/util/email.py", line 23, in send_captcha
    status = send_mail(email_title, email_body, self.email_from, [receive_email, ])
  File "/Users/yi/.virtualenvs/yi3/lib/python3.6/site-packages/django/core/mail/__init__.py", line 62, in send_mail
    return mail.send()
  File "/Users/yi/.virtualenvs/yi3/lib/python3.6/site-packages/django/core/mail/message.py", line 348, in send
    return self.get_connection(fail_silently).send_messages([self])
  File "/Users/yi/.virtualenvs/yi3/lib/python3.6/site-packages/django/core/mail/backends/smtp.py", line 111, in send_messages
    sent = self._send(message)
  File "/Users/yi/.virtualenvs/yi3/lib/python3.6/site-packages/django/core/mail/backends/smtp.py", line 127, in _send
    self.connection.sendmail(from_email, recipients, message.as_bytes(linesep='\r\n'))
  File "/usr/local/Cellar/python/3.6.5/Frameworks/Python.framework/Versions/3.6/lib/python3.6/smtplib.py", line 888, in sendmail
    raise SMTPDataError(code, resp)
smtplib.SMTPDataError: (554, b'DT:SPM 163 smtp8,DMCowAAHP3M9QRtcrUdAGQ--.56660S2 1545290046,please see http://mail.163.com/help/help_spam_16.htm?ip=59.42.191.95&hostid=smtp8&time=1545290046')
[E 20181220 07:14:06 basehttp:124] "POST /api/v1/captcha/ HTTP/1.1" 500 16615
[E 20181220 07:14:09 exception:135] Internal Server Error: /api/v1/captcha/
Traceback (most recent call last):
  File "/Users/yi/.virtualenvs/yi3/lib/python3.6/site-packages/django/core/handlers/exception.py", line 41, in inner
    response = get_response(request)
  File "/Users/yi/.virtualenvs/yi3/lib/python3.6/site-packages/django/core/handlers/base.py", line 187, in _get_response
    response = self.process_exception_by_middleware(e, request)
  File "/Users/yi/.virtualenvs/yi3/lib/python3.6/site-packages/django/core/handlers/base.py", line 185, in _get_response
    response = wrapped_callback(request, *callback_args, **callback_kwargs)
  File "/Users/yi/.virtualenvs/yi3/lib/python3.6/site-packages/django/views/decorators/csrf.py", line 58, in wrapped_view
    return view_func(*args, **kwargs)
  File "/Users/yi/.virtualenvs/yi3/lib/python3.6/site-packages/django/views/generic/base.py", line 68, in view
    return self.dispatch(request, *args, **kwargs)
  File "/Users/yi/.virtualenvs/yi3/lib/python3.6/site-packages/rest_framework/views.py", line 483, in dispatch
    response = self.handle_exception(exc)
  File "/Users/yi/.virtualenvs/yi3/lib/python3.6/site-packages/rest_framework/views.py", line 443, in handle_exception
    self.raise_uncaught_exception(exc)
  File "/Users/yi/.virtualenvs/yi3/lib/python3.6/site-packages/rest_framework/views.py", line 480, in dispatch
    response = handler(request, *args, **kwargs)
  File "/Users/yi/PycharmProjects/djangos/web_chat/chat/api_views/account.py", line 74, in post
    email_helper.send_captcha(receive_email=email)
  File "/Users/yi/PycharmProjects/djangos/web_chat/util/email.py", line 23, in send_captcha
    status = send_mail(email_title, email_body, self.email_from, [receive_email, ])
  File "/Users/yi/.virtualenvs/yi3/lib/python3.6/site-packages/django/core/mail/__init__.py", line 62, in send_mail
    return mail.send()
  File "/Users/yi/.virtualenvs/yi3/lib/python3.6/site-packages/django/core/mail/message.py", line 348, in send
    return self.get_connection(fail_silently).send_messages([self])
  File "/Users/yi/.virtualenvs/yi3/lib/python3.6/site-packages/django/core/mail/backends/smtp.py", line 111, in send_messages
    sent = self._send(message)
  File "/Users/yi/.virtualenvs/yi3/lib/python3.6/site-packages/django/core/mail/backends/smtp.py", line 127, in _send
    self.connection.sendmail(from_email, recipients, message.as_bytes(linesep='\r\n'))
  File "/usr/local/Cellar/python/3.6.5/Frameworks/Python.framework/Versions/3.6/lib/python3.6/smtplib.py", line 888, in sendmail
    raise SMTPDataError(code, resp)
smtplib.SMTPDataError: (554, b'DT:SPM 163 smtp9,DcCowACX1RdBQRtctliPAA--.7252S2 1545290049,please see http://mail.163.com/help/help_spam_16.htm?ip=59.42.191.95&hostid=smtp9&time=1545290049')
[E 20181220 07:14:09 basehttp:124] "POST /api/v1/captcha/ HTTP/1.1" 500 16613
[E 20181220 07:14:11 exception:135] Internal Server Error: /api/v1/captcha/
Traceback (most recent call last):
  File "/Users/yi/.virtualenvs/yi3/lib/python3.6/site-packages/django/core/handlers/exception.py", line 41, in inner
    response = get_response(request)
  File "/Users/yi/.virtualenvs/yi3/lib/python3.6/site-packages/django/core/handlers/base.py", line 187, in _get_response
    response = self.process_exception_by_middleware(e, request)
  File "/Users/yi/.virtualenvs/yi3/lib/python3.6/site-packages/django/core/handlers/base.py", line 185, in _get_response
    response = wrapped_callback(request, *callback_args, **callback_kwargs)
  File "/Users/yi/.virtualenvs/yi3/lib/python3.6/site-packages/django/views/decorators/csrf.py", line 58, in wrapped_view
    return view_func(*args, **kwargs)
  File "/Users/yi/.virtualenvs/yi3/lib/python3.6/site-packages/django/views/generic/base.py", line 68, in view
    return self.dispatch(request, *args, **kwargs)
  File "/Users/yi/.virtualenvs/yi3/lib/python3.6/site-packages/rest_framework/views.py", line 483, in dispatch
    response = self.handle_exception(exc)
  File "/Users/yi/.virtualenvs/yi3/lib/python3.6/site-packages/rest_framework/views.py", line 443, in handle_exception
    self.raise_uncaught_exception(exc)
  File "/Users/yi/.virtualenvs/yi3/lib/python3.6/site-packages/rest_framework/views.py", line 480, in dispatch
    response = handler(request, *args, **kwargs)
  File "/Users/yi/PycharmProjects/djangos/web_chat/chat/api_views/account.py", line 74, in post
    email_helper.send_captcha(receive_email=email)
  File "/Users/yi/PycharmProjects/djangos/web_chat/util/email.py", line 23, in send_captcha
    status = send_mail(email_title, email_body, self.email_from, [receive_email, ])
  File "/Users/yi/.virtualenvs/yi3/lib/python3.6/site-packages/django/core/mail/__init__.py", line 62, in send_mail
    return mail.send()
  File "/Users/yi/.virtualenvs/yi3/lib/python3.6/site-packages/django/core/mail/message.py", line 348, in send
    return self.get_connection(fail_silently).send_messages([self])
  File "/Users/yi/.virtualenvs/yi3/lib/python3.6/site-packages/django/core/mail/backends/smtp.py", line 111, in send_messages
    sent = self._send(message)
  File "/Users/yi/.virtualenvs/yi3/lib/python3.6/site-packages/django/core/mail/backends/smtp.py", line 127, in _send
    self.connection.sendmail(from_email, recipients, message.as_bytes(linesep='\r\n'))
  File "/usr/local/Cellar/python/3.6.5/Frameworks/Python.framework/Versions/3.6/lib/python3.6/smtplib.py", line 888, in sendmail
    raise SMTPDataError(code, resp)
smtplib.SMTPDataError: (554, b'DT:SPM 163 smtp10,DsCowAAHuuRCQRtcozSzGA--.56541S2 1545290051,please see http://mail.163.com/help/help_spam_16.htm?ip=59.42.191.95&hostid=smtp10&time=1545290051')
[E 20181220 07:14:11 basehttp:124] "POST /api/v1/captcha/ HTTP/1.1" 500 16619
[E 20181220 07:14:12 exception:135] Internal Server Error: /api/v1/captcha/
Traceback (most recent call last):
  File "/Users/yi/.virtualenvs/yi3/lib/python3.6/site-packages/django/core/handlers/exception.py", line 41, in inner
    response = get_response(request)
  File "/Users/yi/.virtualenvs/yi3/lib/python3.6/site-packages/django/core/handlers/base.py", line 187, in _get_response
    response = self.process_exception_by_middleware(e, request)
  File "/Users/yi/.virtualenvs/yi3/lib/python3.6/site-packages/django/core/handlers/base.py", line 185, in _get_response
    response = wrapped_callback(request, *callback_args, **callback_kwargs)
  File "/Users/yi/.virtualenvs/yi3/lib/python3.6/site-packages/django/views/decorators/csrf.py", line 58, in wrapped_view
    return view_func(*args, **kwargs)
  File "/Users/yi/.virtualenvs/yi3/lib/python3.6/site-packages/django/views/generic/base.py", line 68, in view
    return self.dispatch(request, *args, **kwargs)
  File "/Users/yi/.virtualenvs/yi3/lib/python3.6/site-packages/rest_framework/views.py", line 483, in dispatch
    response = self.handle_exception(exc)
  File "/Users/yi/.virtualenvs/yi3/lib/python3.6/site-packages/rest_framework/views.py", line 443, in handle_exception
    self.raise_uncaught_exception(exc)
  File "/Users/yi/.virtualenvs/yi3/lib/python3.6/site-packages/rest_framework/views.py", line 480, in dispatch
    response = handler(request, *args, **kwargs)
  File "/Users/yi/PycharmProjects/djangos/web_chat/chat/api_views/account.py", line 74, in post
    email_helper.send_captcha(receive_email=email)
  File "/Users/yi/PycharmProjects/djangos/web_chat/util/email.py", line 23, in send_captcha
    status = send_mail(email_title, email_body, self.email_from, [receive_email, ])
  File "/Users/yi/.virtualenvs/yi3/lib/python3.6/site-packages/django/core/mail/__init__.py", line 62, in send_mail
    return mail.send()
  File "/Users/yi/.virtualenvs/yi3/lib/python3.6/site-packages/django/core/mail/message.py", line 348, in send
    return self.get_connection(fail_silently).send_messages([self])
  File "/Users/yi/.virtualenvs/yi3/lib/python3.6/site-packages/django/core/mail/backends/smtp.py", line 111, in send_messages
    sent = self._send(message)
  File "/Users/yi/.virtualenvs/yi3/lib/python3.6/site-packages/django/core/mail/backends/smtp.py", line 127, in _send
    self.connection.sendmail(from_email, recipients, message.as_bytes(linesep='\r\n'))
  File "/usr/local/Cellar/python/3.6.5/Frameworks/Python.framework/Versions/3.6/lib/python3.6/smtplib.py", line 888, in sendmail
    raise SMTPDataError(code, resp)
smtplib.SMTPDataError: (554, b'DT:SPM 163 smtp14,EsCowAAn1oVDQRtclw34Fw--.7394S2 1545290052,please see http://mail.163.com/help/help_spam_16.htm?ip=59.42.191.95&hostid=smtp14&time=1545290052')
[E 20181220 07:14:12 basehttp:124] "POST /api/v1/captcha/ HTTP/1.1" 500 16617
[E 20181220 07:14:34 exception:135] Internal Server Error: /api/v1/captcha/
Traceback (most recent call last):
  File "/Users/yi/.virtualenvs/yi3/lib/python3.6/site-packages/django/core/handlers/exception.py", line 41, in inner
    response = get_response(request)
  File "/Users/yi/.virtualenvs/yi3/lib/python3.6/site-packages/django/core/handlers/base.py", line 187, in _get_response
    response = self.process_exception_by_middleware(e, request)
  File "/Users/yi/.virtualenvs/yi3/lib/python3.6/site-packages/django/core/handlers/base.py", line 185, in _get_response
    response = wrapped_callback(request, *callback_args, **callback_kwargs)
  File "/Users/yi/.virtualenvs/yi3/lib/python3.6/site-packages/django/views/decorators/csrf.py", line 58, in wrapped_view
    return view_func(*args, **kwargs)
  File "/Users/yi/.virtualenvs/yi3/lib/python3.6/site-packages/django/views/generic/base.py", line 68, in view
    return self.dispatch(request, *args, **kwargs)
  File "/Users/yi/.virtualenvs/yi3/lib/python3.6/site-packages/rest_framework/views.py", line 483, in dispatch
    response = self.handle_exception(exc)
  File "/Users/yi/.virtualenvs/yi3/lib/python3.6/site-packages/rest_framework/views.py", line 443, in handle_exception
    self.raise_uncaught_exception(exc)
  File "/Users/yi/.virtualenvs/yi3/lib/python3.6/site-packages/rest_framework/views.py", line 480, in dispatch
    response = handler(request, *args, **kwargs)
  File "/Users/yi/PycharmProjects/djangos/web_chat/chat/api_views/account.py", line 74, in post
    email_helper.send_captcha(receive_email=email)
  File "/Users/yi/PycharmProjects/djangos/web_chat/util/email.py", line 23, in send_captcha
    status = send_mail(email_title, email_body, self.email_from, [receive_email, ])
  File "/Users/yi/.virtualenvs/yi3/lib/python3.6/site-packages/django/core/mail/__init__.py", line 62, in send_mail
    return mail.send()
  File "/Users/yi/.virtualenvs/yi3/lib/python3.6/site-packages/django/core/mail/message.py", line 348, in send
    return self.get_connection(fail_silently).send_messages([self])
  File "/Users/yi/.virtualenvs/yi3/lib/python3.6/site-packages/django/core/mail/backends/smtp.py", line 111, in send_messages
    sent = self._send(message)
  File "/Users/yi/.virtualenvs/yi3/lib/python3.6/site-packages/django/core/mail/backends/smtp.py", line 127, in _send
    self.connection.sendmail(from_email, recipients, message.as_bytes(linesep='\r\n'))
  File "/usr/local/Cellar/python/3.6.5/Frameworks/Python.framework/Versions/3.6/lib/python3.6/smtplib.py", line 888, in sendmail
    raise SMTPDataError(code, resp)
smtplib.SMTPDataError: (554, b'DT:SPM 163 smtp11,D8CowADn0ilZQRtcbko4EA--.29547S2 1545290074,please see http://mail.163.com/help/help_spam_16.htm?ip=59.42.191.95&hostid=smtp11&time=1545290074')
[E 20181220 07:14:34 basehttp:124] "POST /api/v1/captcha/ HTTP/1.1" 500 16619
[E 20181220 07:14:35 exception:135] Internal Server Error: /api/v1/captcha/
Traceback (most recent call last):
  File "/Users/yi/.virtualenvs/yi3/lib/python3.6/site-packages/django/core/handlers/exception.py", line 41, in inner
    response = get_response(request)
  File "/Users/yi/.virtualenvs/yi3/lib/python3.6/site-packages/django/core/handlers/base.py", line 187, in _get_response
    response = self.process_exception_by_middleware(e, request)
  File "/Users/yi/.virtualenvs/yi3/lib/python3.6/site-packages/django/core/handlers/base.py", line 185, in _get_response
    response = wrapped_callback(request, *callback_args, **callback_kwargs)
  File "/Users/yi/.virtualenvs/yi3/lib/python3.6/site-packages/django/views/decorators/csrf.py", line 58, in wrapped_view
    return view_func(*args, **kwargs)
  File "/Users/yi/.virtualenvs/yi3/lib/python3.6/site-packages/django/views/generic/base.py", line 68, in view
    return self.dispatch(request, *args, **kwargs)
  File "/Users/yi/.virtualenvs/yi3/lib/python3.6/site-packages/rest_framework/views.py", line 483, in dispatch
    response = self.handle_exception(exc)
  File "/Users/yi/.virtualenvs/yi3/lib/python3.6/site-packages/rest_framework/views.py", line 443, in handle_exception
    self.raise_uncaught_exception(exc)
  File "/Users/yi/.virtualenvs/yi3/lib/python3.6/site-packages/rest_framework/views.py", line 480, in dispatch
    response = handler(request, *args, **kwargs)
  File "/Users/yi/PycharmProjects/djangos/web_chat/chat/api_views/account.py", line 74, in post
    email_helper.send_captcha(receive_email=email)
  File "/Users/yi/PycharmProjects/djangos/web_chat/util/email.py", line 23, in send_captcha
    status = send_mail(email_title, email_body, self.email_from, [receive_email, ])
  File "/Users/yi/.virtualenvs/yi3/lib/python3.6/site-packages/django/core/mail/__init__.py", line 62, in send_mail
    return mail.send()
  File "/Users/yi/.virtualenvs/yi3/lib/python3.6/site-packages/django/core/mail/message.py", line 348, in send
    return self.get_connection(fail_silently).send_messages([self])
  File "/Users/yi/.virtualenvs/yi3/lib/python3.6/site-packages/django/core/mail/backends/smtp.py", line 111, in send_messages
    sent = self._send(message)
  File "/Users/yi/.virtualenvs/yi3/lib/python3.6/site-packages/django/core/mail/backends/smtp.py", line 127, in _send
    self.connection.sendmail(from_email, recipients, message.as_bytes(linesep='\r\n'))
  File "/usr/local/Cellar/python/3.6.5/Frameworks/Python.framework/Versions/3.6/lib/python3.6/smtplib.py", line 888, in sendmail
    raise SMTPDataError(code, resp)
smtplib.SMTPDataError: (554, b'DT:SPM 163 smtp12,EMCowAA3nQpbQRtc6RgcEA--.29701S2 1545290075,please see http://mail.163.com/help/help_spam_16.htm?ip=59.42.191.95&hostid=smtp12&time=1545290075')
[E 20181220 07:14:35 basehttp:124] "POST /api/v1/captcha/ HTTP/1.1" 500 16619
[E 20181220 07:14:42 exception:135] Internal Server Error: /api/v1/captcha/
Traceback (most recent call last):
  File "/Users/yi/.virtualenvs/yi3/lib/python3.6/site-packages/django/core/handlers/exception.py", line 41, in inner
    response = get_response(request)
  File "/Users/yi/.virtualenvs/yi3/lib/python3.6/site-packages/django/core/handlers/base.py", line 187, in _get_response
    response = self.process_exception_by_middleware(e, request)
  File "/Users/yi/.virtualenvs/yi3/lib/python3.6/site-packages/django/core/handlers/base.py", line 185, in _get_response
    response = wrapped_callback(request, *callback_args, **callback_kwargs)
  File "/Users/yi/.virtualenvs/yi3/lib/python3.6/site-packages/django/views/decorators/csrf.py", line 58, in wrapped_view
    return view_func(*args, **kwargs)
  File "/Users/yi/.virtualenvs/yi3/lib/python3.6/site-packages/django/views/generic/base.py", line 68, in view
    return self.dispatch(request, *args, **kwargs)
  File "/Users/yi/.virtualenvs/yi3/lib/python3.6/site-packages/rest_framework/views.py", line 483, in dispatch
    response = self.handle_exception(exc)
  File "/Users/yi/.virtualenvs/yi3/lib/python3.6/site-packages/rest_framework/views.py", line 443, in handle_exception
    self.raise_uncaught_exception(exc)
  File "/Users/yi/.virtualenvs/yi3/lib/python3.6/site-packages/rest_framework/views.py", line 480, in dispatch
    response = handler(request, *args, **kwargs)
  File "/Users/yi/PycharmProjects/djangos/web_chat/chat/api_views/account.py", line 74, in post
    email_helper.send_captcha(receive_email=email)
  File "/Users/yi/PycharmProjects/djangos/web_chat/util/email.py", line 23, in send_captcha
    status = send_mail(email_title, email_body, self.email_from, [receive_email, ])
  File "/Users/yi/.virtualenvs/yi3/lib/python3.6/site-packages/django/core/mail/__init__.py", line 62, in send_mail
    return mail.send()
  File "/Users/yi/.virtualenvs/yi3/lib/python3.6/site-packages/django/core/mail/message.py", line 348, in send
    return self.get_connection(fail_silently).send_messages([self])
  File "/Users/yi/.virtualenvs/yi3/lib/python3.6/site-packages/django/core/mail/backends/smtp.py", line 111, in send_messages
    sent = self._send(message)
  File "/Users/yi/.virtualenvs/yi3/lib/python3.6/site-packages/django/core/mail/backends/smtp.py", line 127, in _send
    self.connection.sendmail(from_email, recipients, message.as_bytes(linesep='\r\n'))
  File "/usr/local/Cellar/python/3.6.5/Frameworks/Python.framework/Versions/3.6/lib/python3.6/smtplib.py", line 888, in sendmail
    raise SMTPDataError(code, resp)
smtplib.SMTPDataError: (554, b'DT:SPM 163 smtp7,C8CowABnfn1iQRtcUNATBA--.46818S2 1545290082,please see http://mail.163.com/help/help_spam_16.htm?ip=59.42.191.95&hostid=smtp7&time=1545290082')
[E 20181220 07:14:42 basehttp:124] "POST /api/v1/captcha/ HTTP/1.1" 500 16615
[E 20181220 07:19:49 exception:135] Internal Server Error: /api/v1/captcha/
Traceback (most recent call last):
  File "/Users/yi/.virtualenvs/yi3/lib/python3.6/site-packages/django/core/handlers/exception.py", line 41, in inner
    response = get_response(request)
  File "/Users/yi/.virtualenvs/yi3/lib/python3.6/site-packages/django/core/handlers/base.py", line 187, in _get_response
    response = self.process_exception_by_middleware(e, request)
  File "/Users/yi/.virtualenvs/yi3/lib/python3.6/site-packages/django/core/handlers/base.py", line 185, in _get_response
    response = wrapped_callback(request, *callback_args, **callback_kwargs)
  File "/Users/yi/.virtualenvs/yi3/lib/python3.6/site-packages/django/views/decorators/csrf.py", line 58, in wrapped_view
    return view_func(*args, **kwargs)
  File "/Users/yi/.virtualenvs/yi3/lib/python3.6/site-packages/django/views/generic/base.py", line 68, in view
    return self.dispatch(request, *args, **kwargs)
  File "/Users/yi/.virtualenvs/yi3/lib/python3.6/site-packages/rest_framework/views.py", line 483, in dispatch
    response = self.handle_exception(exc)
  File "/Users/yi/.virtualenvs/yi3/lib/python3.6/site-packages/rest_framework/views.py", line 443, in handle_exception
    self.raise_uncaught_exception(exc)
  File "/Users/yi/.virtualenvs/yi3/lib/python3.6/site-packages/rest_framework/views.py", line 480, in dispatch
    response = handler(request, *args, **kwargs)
  File "/Users/yi/PycharmProjects/djangos/web_chat/chat/api_views/account.py", line 74, in post
    email_helper.send_captcha(receive_email=email)
  File "/Users/yi/PycharmProjects/djangos/web_chat/util/email.py", line 23, in send_captcha
    status = send_mail(email_title, email_body, self.email_from, [receive_email, ])
  File "/Users/yi/.virtualenvs/yi3/lib/python3.6/site-packages/django/core/mail/__init__.py", line 62, in send_mail
    return mail.send()
  File "/Users/yi/.virtualenvs/yi3/lib/python3.6/site-packages/django/core/mail/message.py", line 348, in send
    return self.get_connection(fail_silently).send_messages([self])
  File "/Users/yi/.virtualenvs/yi3/lib/python3.6/site-packages/django/core/mail/backends/smtp.py", line 111, in send_messages
    sent = self._send(message)
  File "/Users/yi/.virtualenvs/yi3/lib/python3.6/site-packages/django/core/mail/backends/smtp.py", line 127, in _send
    self.connection.sendmail(from_email, recipients, message.as_bytes(linesep='\r\n'))
  File "/usr/local/Cellar/python/3.6.5/Frameworks/Python.framework/Versions/3.6/lib/python3.6/smtplib.py", line 888, in sendmail
    raise SMTPDataError(code, resp)
smtplib.SMTPDataError: (554, b'DT:SPM 163 smtp8,DMCowABXrzOUQhtcu69AGQ--.58082S2 1545290389,please see http://mail.163.com/help/help_spam_16.htm?ip=59.42.191.95&hostid=smtp8&time=1545290389')
[E 20181220 07:19:49 basehttp:124] "POST /api/v1/captcha/ HTTP/1.1" 500 16621
[E 20181220 07:22:11 exception:135] Internal Server Error: /api/v1/captcha/
Traceback (most recent call last):
  File "/Users/yi/.virtualenvs/yi3/lib/python3.6/site-packages/django/core/handlers/exception.py", line 41, in inner
    response = get_response(request)
  File "/Users/yi/.virtualenvs/yi3/lib/python3.6/site-packages/django/core/handlers/base.py", line 187, in _get_response
    response = self.process_exception_by_middleware(e, request)
  File "/Users/yi/.virtualenvs/yi3/lib/python3.6/site-packages/django/core/handlers/base.py", line 185, in _get_response
    response = wrapped_callback(request, *callback_args, **callback_kwargs)
  File "/Users/yi/.virtualenvs/yi3/lib/python3.6/site-packages/django/views/decorators/csrf.py", line 58, in wrapped_view
    return view_func(*args, **kwargs)
  File "/Users/yi/.virtualenvs/yi3/lib/python3.6/site-packages/django/views/generic/base.py", line 68, in view
    return self.dispatch(request, *args, **kwargs)
  File "/Users/yi/.virtualenvs/yi3/lib/python3.6/site-packages/rest_framework/views.py", line 483, in dispatch
    response = self.handle_exception(exc)
  File "/Users/yi/.virtualenvs/yi3/lib/python3.6/site-packages/rest_framework/views.py", line 443, in handle_exception
    self.raise_uncaught_exception(exc)
  File "/Users/yi/.virtualenvs/yi3/lib/python3.6/site-packages/rest_framework/views.py", line 480, in dispatch
    response = handler(request, *args, **kwargs)
  File "/Users/yi/PycharmProjects/djangos/web_chat/chat/api_views/account.py", line 74, in post
    email_helper.send_captcha(receive_email=email)
  File "/Users/yi/PycharmProjects/djangos/web_chat/util/email.py", line 23, in send_captcha
    status = send_mail(email_title, email_body, self.email_from, [receive_email, ])
  File "/Users/yi/.virtualenvs/yi3/lib/python3.6/site-packages/django/core/mail/__init__.py", line 62, in send_mail
    return mail.send()
  File "/Users/yi/.virtualenvs/yi3/lib/python3.6/site-packages/django/core/mail/message.py", line 348, in send
    return self.get_connection(fail_silently).send_messages([self])
  File "/Users/yi/.virtualenvs/yi3/lib/python3.6/site-packages/django/core/mail/backends/smtp.py", line 111, in send_messages
    sent = self._send(message)
  File "/Users/yi/.virtualenvs/yi3/lib/python3.6/site-packages/django/core/mail/backends/smtp.py", line 127, in _send
    self.connection.sendmail(from_email, recipients, message.as_bytes(linesep='\r\n'))
  File "/usr/local/Cellar/python/3.6.5/Frameworks/Python.framework/Versions/3.6/lib/python3.6/smtplib.py", line 888, in sendmail
    raise SMTPDataError(code, resp)
smtplib.SMTPDataError: (554, b'DT:SPM 163 smtp11,D8CowAAnCjwjQxtcUDc5EA--.26388S2 1545290531,please see http://mail.163.com/help/help_spam_16.htm?ip=59.42.191.95&hostid=smtp11&time=1545290531')
[E 20181220 07:22:11 basehttp:124] "POST /api/v1/captcha/ HTTP/1.1" 500 16624
[E 20181220 07:24:39 exception:135] Internal Server Error: /api/v1/captcha/
Traceback (most recent call last):
  File "/Users/yi/.virtualenvs/yi3/lib/python3.6/site-packages/django/core/handlers/exception.py", line 41, in inner
    response = get_response(request)
  File "/Users/yi/.virtualenvs/yi3/lib/python3.6/site-packages/django/core/handlers/base.py", line 187, in _get_response
    response = self.process_exception_by_middleware(e, request)
  File "/Users/yi/.virtualenvs/yi3/lib/python3.6/site-packages/django/core/handlers/base.py", line 185, in _get_response
    response = wrapped_callback(request, *callback_args, **callback_kwargs)
  File "/Users/yi/.virtualenvs/yi3/lib/python3.6/site-packages/django/views/decorators/csrf.py", line 58, in wrapped_view
    return view_func(*args, **kwargs)
  File "/Users/yi/.virtualenvs/yi3/lib/python3.6/site-packages/django/views/generic/base.py", line 68, in view
    return self.dispatch(request, *args, **kwargs)
  File "/Users/yi/.virtualenvs/yi3/lib/python3.6/site-packages/rest_framework/views.py", line 483, in dispatch
    response = self.handle_exception(exc)
  File "/Users/yi/.virtualenvs/yi3/lib/python3.6/site-packages/rest_framework/views.py", line 443, in handle_exception
    self.raise_uncaught_exception(exc)
  File "/Users/yi/.virtualenvs/yi3/lib/python3.6/site-packages/rest_framework/views.py", line 480, in dispatch
    response = handler(request, *args, **kwargs)
  File "/Users/yi/PycharmProjects/djangos/web_chat/chat/api_views/account.py", line 74, in post
    email_helper.send_captcha(receive_email=email)
  File "/Users/yi/PycharmProjects/djangos/web_chat/util/email.py", line 23, in send_captcha
    status = send_mail(email_title, email_body, self.email_from, [receive_email, ])
  File "/Users/yi/.virtualenvs/yi3/lib/python3.6/site-packages/django/core/mail/__init__.py", line 62, in send_mail
    return mail.send()
  File "/Users/yi/.virtualenvs/yi3/lib/python3.6/site-packages/django/core/mail/message.py", line 348, in send
    return self.get_connection(fail_silently).send_messages([self])
  File "/Users/yi/.virtualenvs/yi3/lib/python3.6/site-packages/django/core/mail/backends/smtp.py", line 111, in send_messages
    sent = self._send(message)
  File "/Users/yi/.virtualenvs/yi3/lib/python3.6/site-packages/django/core/mail/backends/smtp.py", line 127, in _send
    self.connection.sendmail(from_email, recipients, message.as_bytes(linesep='\r\n'))
  File "/usr/local/Cellar/python/3.6.5/Frameworks/Python.framework/Versions/3.6/lib/python3.6/smtplib.py", line 867, in sendmail
    raise SMTPSenderRefused(code, resp, from_addr)
smtplib.SMTPSenderRefused: (550, b'Invalid User', '=?utf-8?b?5L+u5LuU56eR5oqA?= <=?utf-8?q?www=2Ejdecree=2Ecom?=>')
[E 20181220 07:24:39 basehttp:124] "POST /api/v1/captcha/ HTTP/1.1" 500 16492
[E 20181220 07:29:56 exception:135] Internal Server Error: /api/v1/captcha/
Traceback (most recent call last):
  File "/Users/yi/.virtualenvs/yi3/lib/python3.6/site-packages/django/core/handlers/exception.py", line 41, in inner
    response = get_response(request)
  File "/Users/yi/.virtualenvs/yi3/lib/python3.6/site-packages/django/core/handlers/base.py", line 187, in _get_response
    response = self.process_exception_by_middleware(e, request)
  File "/Users/yi/.virtualenvs/yi3/lib/python3.6/site-packages/django/core/handlers/base.py", line 185, in _get_response
    response = wrapped_callback(request, *callback_args, **callback_kwargs)
  File "/Users/yi/.virtualenvs/yi3/lib/python3.6/site-packages/django/views/decorators/csrf.py", line 58, in wrapped_view
    return view_func(*args, **kwargs)
  File "/Users/yi/.virtualenvs/yi3/lib/python3.6/site-packages/django/views/generic/base.py", line 68, in view
    return self.dispatch(request, *args, **kwargs)
  File "/Users/yi/.virtualenvs/yi3/lib/python3.6/site-packages/rest_framework/views.py", line 483, in dispatch
    response = self.handle_exception(exc)
  File "/Users/yi/.virtualenvs/yi3/lib/python3.6/site-packages/rest_framework/views.py", line 443, in handle_exception
    self.raise_uncaught_exception(exc)
  File "/Users/yi/.virtualenvs/yi3/lib/python3.6/site-packages/rest_framework/views.py", line 480, in dispatch
    response = handler(request, *args, **kwargs)
  File "/Users/yi/PycharmProjects/djangos/web_chat/chat/api_views/account.py", line 74, in post
    email_helper.send_captcha(receive_email=email)
  File "/Users/yi/PycharmProjects/djangos/web_chat/util/email.py", line 23, in send_captcha
    status = send_mail(email_title, email_body, self.email_from, [receive_email, ])
  File "/Users/yi/.virtualenvs/yi3/lib/python3.6/site-packages/django/core/mail/__init__.py", line 62, in send_mail
    return mail.send()
  File "/Users/yi/.virtualenvs/yi3/lib/python3.6/site-packages/django/core/mail/message.py", line 348, in send
    return self.get_connection(fail_silently).send_messages([self])
  File "/Users/yi/.virtualenvs/yi3/lib/python3.6/site-packages/django/core/mail/backends/smtp.py", line 111, in send_messages
    sent = self._send(message)
  File "/Users/yi/.virtualenvs/yi3/lib/python3.6/site-packages/django/core/mail/backends/smtp.py", line 127, in _send
    self.connection.sendmail(from_email, recipients, message.as_bytes(linesep='\r\n'))
  File "/usr/local/Cellar/python/3.6.5/Frameworks/Python.framework/Versions/3.6/lib/python3.6/smtplib.py", line 888, in sendmail
    raise SMTPDataError(code, resp)
smtplib.SMTPDataError: (554, b'DT:SPM 163 smtp11,D8CowACHiD_0RBtc1wY6EA--.27205S2 1545290996,please see http://mail.163.com/help/help_spam_16.htm?ip=59.42.191.95&hostid=smtp11&time=1545290996')
[E 20181220 07:29:56 basehttp:124] "POST /api/v1/captcha/ HTTP/1.1" 500 16631
[E 20181220 07:31:48 exception:135] Internal Server Error: /api/v1/captcha/
Traceback (most recent call last):
  File "/Users/yi/.virtualenvs/yi3/lib/python3.6/site-packages/django/core/handlers/exception.py", line 41, in inner
    response = get_response(request)
  File "/Users/yi/.virtualenvs/yi3/lib/python3.6/site-packages/django/core/handlers/base.py", line 187, in _get_response
    response = self.process_exception_by_middleware(e, request)
  File "/Users/yi/.virtualenvs/yi3/lib/python3.6/site-packages/django/core/handlers/base.py", line 185, in _get_response
    response = wrapped_callback(request, *callback_args, **callback_kwargs)
  File "/Users/yi/.virtualenvs/yi3/lib/python3.6/site-packages/django/views/decorators/csrf.py", line 58, in wrapped_view
    return view_func(*args, **kwargs)
  File "/Users/yi/.virtualenvs/yi3/lib/python3.6/site-packages/django/views/generic/base.py", line 68, in view
    return self.dispatch(request, *args, **kwargs)
  File "/Users/yi/.virtualenvs/yi3/lib/python3.6/site-packages/rest_framework/views.py", line 483, in dispatch
    response = self.handle_exception(exc)
  File "/Users/yi/.virtualenvs/yi3/lib/python3.6/site-packages/rest_framework/views.py", line 443, in handle_exception
    self.raise_uncaught_exception(exc)
  File "/Users/yi/.virtualenvs/yi3/lib/python3.6/site-packages/rest_framework/views.py", line 480, in dispatch
    response = handler(request, *args, **kwargs)
  File "/Users/yi/PycharmProjects/djangos/web_chat/chat/api_views/account.py", line 74, in post
    email_helper.send_captcha(receive_email=email)
  File "/Users/yi/PycharmProjects/djangos/web_chat/util/email.py", line 23, in send_captcha
    status = send_mail(email_title, email_body, self.email_from, [receive_email, ])
  File "/Users/yi/.virtualenvs/yi3/lib/python3.6/site-packages/django/core/mail/__init__.py", line 62, in send_mail
    return mail.send()
  File "/Users/yi/.virtualenvs/yi3/lib/python3.6/site-packages/django/core/mail/message.py", line 348, in send
    return self.get_connection(fail_silently).send_messages([self])
  File "/Users/yi/.virtualenvs/yi3/lib/python3.6/site-packages/django/core/mail/backends/smtp.py", line 111, in send_messages
    sent = self._send(message)
  File "/Users/yi/.virtualenvs/yi3/lib/python3.6/site-packages/django/core/mail/backends/smtp.py", line 127, in _send
    self.connection.sendmail(from_email, recipients, message.as_bytes(linesep='\r\n'))
  File "/usr/local/Cellar/python/3.6.5/Frameworks/Python.framework/Versions/3.6/lib/python3.6/smtplib.py", line 888, in sendmail
    raise SMTPDataError(code, resp)
smtplib.SMTPDataError: (554, b'DT:SPM 163 smtp14,EsCowAB3931jRRtcmtH5Fw--.7695S2 1545291108,please see http://mail.163.com/help/help_spam_16.htm?ip=59.42.191.95&hostid=smtp14&time=1545291108')
[E 20181220 07:31:48 basehttp:124] "POST /api/v1/captcha/ HTTP/1.1" 500 16617
[E 20181220 07:34:35 exception:135] Internal Server Error: /api/v1/captcha/
Traceback (most recent call last):
  File "/Users/yi/.virtualenvs/yi3/lib/python3.6/site-packages/django/core/handlers/exception.py", line 41, in inner
    response = get_response(request)
  File "/Users/yi/.virtualenvs/yi3/lib/python3.6/site-packages/django/core/handlers/base.py", line 187, in _get_response
    response = self.process_exception_by_middleware(e, request)
  File "/Users/yi/.virtualenvs/yi3/lib/python3.6/site-packages/django/core/handlers/base.py", line 185, in _get_response
    response = wrapped_callback(request, *callback_args, **callback_kwargs)
  File "/Users/yi/.virtualenvs/yi3/lib/python3.6/site-packages/django/views/decorators/csrf.py", line 58, in wrapped_view
    return view_func(*args, **kwargs)
  File "/Users/yi/.virtualenvs/yi3/lib/python3.6/site-packages/django/views/generic/base.py", line 68, in view
    return self.dispatch(request, *args, **kwargs)
  File "/Users/yi/.virtualenvs/yi3/lib/python3.6/site-packages/rest_framework/views.py", line 483, in dispatch
    response = self.handle_exception(exc)
  File "/Users/yi/.virtualenvs/yi3/lib/python3.6/site-packages/rest_framework/views.py", line 443, in handle_exception
    self.raise_uncaught_exception(exc)
  File "/Users/yi/.virtualenvs/yi3/lib/python3.6/site-packages/rest_framework/views.py", line 480, in dispatch
    response = handler(request, *args, **kwargs)
  File "/Users/yi/PycharmProjects/djangos/web_chat/chat/api_views/account.py", line 74, in post
    email_helper.send_captcha(receive_email=email)
  File "/Users/yi/PycharmProjects/djangos/web_chat/util/email.py", line 23, in send_captcha
    status = send_mail(email_title, email_body, self.email_from, [receive_email, ])
  File "/Users/yi/.virtualenvs/yi3/lib/python3.6/site-packages/django/core/mail/__init__.py", line 62, in send_mail
    return mail.send()
  File "/Users/yi/.virtualenvs/yi3/lib/python3.6/site-packages/django/core/mail/message.py", line 348, in send
    return self.get_connection(fail_silently).send_messages([self])
  File "/Users/yi/.virtualenvs/yi3/lib/python3.6/site-packages/django/core/mail/backends/smtp.py", line 111, in send_messages
    sent = self._send(message)
  File "/Users/yi/.virtualenvs/yi3/lib/python3.6/site-packages/django/core/mail/backends/smtp.py", line 127, in _send
    self.connection.sendmail(from_email, recipients, message.as_bytes(linesep='\r\n'))
  File "/usr/local/Cellar/python/3.6.5/Frameworks/Python.framework/Versions/3.6/lib/python3.6/smtplib.py", line 888, in sendmail
    raise SMTPDataError(code, resp)
smtplib.SMTPDataError: (554, b'DT:SPM 163 smtp11,D8CowAA3mzwKRhtcj5E6EA--.26957S2 1545291275,please see http://mail.163.com/help/help_spam_16.htm?ip=59.42.191.95&hostid=smtp11&time=1545291275')
[E 20181220 07:34:35 basehttp:124] "POST /api/v1/captcha/ HTTP/1.1" 500 16619
[I 20181220 07:36:24 basehttp:124] "POST /api/v1/captcha/ HTTP/1.1" 200 13
[E 20181220 07:38:21 exception:135] Internal Server Error: /api/v1/captcha/
Traceback (most recent call last):
  File "/Users/yi/.virtualenvs/yi3/lib/python3.6/site-packages/django/core/handlers/exception.py", line 41, in inner
    response = get_response(request)
  File "/Users/yi/.virtualenvs/yi3/lib/python3.6/site-packages/django/core/handlers/base.py", line 187, in _get_response
    response = self.process_exception_by_middleware(e, request)
  File "/Users/yi/.virtualenvs/yi3/lib/python3.6/site-packages/django/core/handlers/base.py", line 185, in _get_response
    response = wrapped_callback(request, *callback_args, **callback_kwargs)
  File "/Users/yi/.virtualenvs/yi3/lib/python3.6/site-packages/django/views/decorators/csrf.py", line 58, in wrapped_view
    return view_func(*args, **kwargs)
  File "/Users/yi/.virtualenvs/yi3/lib/python3.6/site-packages/django/views/generic/base.py", line 68, in view
    return self.dispatch(request, *args, **kwargs)
  File "/Users/yi/.virtualenvs/yi3/lib/python3.6/site-packages/rest_framework/views.py", line 483, in dispatch
    response = self.handle_exception(exc)
  File "/Users/yi/.virtualenvs/yi3/lib/python3.6/site-packages/rest_framework/views.py", line 443, in handle_exception
    self.raise_uncaught_exception(exc)
  File "/Users/yi/.virtualenvs/yi3/lib/python3.6/site-packages/rest_framework/views.py", line 480, in dispatch
    response = handler(request, *args, **kwargs)
  File "/Users/yi/PycharmProjects/djangos/web_chat/chat/api_views/account.py", line 74, in post
    email_helper.send_captcha(receive_email=email)
  File "/Users/yi/PycharmProjects/djangos/web_chat/util/email.py", line 23, in send_captcha
    status = send_mail(email_title, email_body, self.email_from, [self.email_from, receive_email])
  File "/Users/yi/.virtualenvs/yi3/lib/python3.6/site-packages/django/core/mail/__init__.py", line 62, in send_mail
    return mail.send()
  File "/Users/yi/.virtualenvs/yi3/lib/python3.6/site-packages/django/core/mail/message.py", line 348, in send
    return self.get_connection(fail_silently).send_messages([self])
  File "/Users/yi/.virtualenvs/yi3/lib/python3.6/site-packages/django/core/mail/backends/smtp.py", line 111, in send_messages
    sent = self._send(message)
  File "/Users/yi/.virtualenvs/yi3/lib/python3.6/site-packages/django/core/mail/backends/smtp.py", line 127, in _send
    self.connection.sendmail(from_email, recipients, message.as_bytes(linesep='\r\n'))
  File "/usr/local/Cellar/python/3.6.5/Frameworks/Python.framework/Versions/3.6/lib/python3.6/smtplib.py", line 888, in sendmail
    raise SMTPDataError(code, resp)
smtplib.SMTPDataError: (554, b'DT:SPM 163 smtp11,D8CowABXUSTtRhtcigI7EA--.26577S2 1545291501,please see http://mail.163.com/help/help_spam_16.htm?ip=59.42.191.95&hostid=smtp11&time=1545291501')
[E 20181220 07:38:21 basehttp:124] "POST /api/v1/captcha/ HTTP/1.1" 500 16634
[E 20181220 07:40:04 exception:135] Internal Server Error: /api/v1/captcha/
Traceback (most recent call last):
  File "/Users/yi/.virtualenvs/yi3/lib/python3.6/site-packages/django/core/handlers/exception.py", line 41, in inner
    response = get_response(request)
  File "/Users/yi/.virtualenvs/yi3/lib/python3.6/site-packages/django/core/handlers/base.py", line 187, in _get_response
    response = self.process_exception_by_middleware(e, request)
  File "/Users/yi/.virtualenvs/yi3/lib/python3.6/site-packages/django/core/handlers/base.py", line 185, in _get_response
    response = wrapped_callback(request, *callback_args, **callback_kwargs)
  File "/Users/yi/.virtualenvs/yi3/lib/python3.6/site-packages/django/views/decorators/csrf.py", line 58, in wrapped_view
    return view_func(*args, **kwargs)
  File "/Users/yi/.virtualenvs/yi3/lib/python3.6/site-packages/django/views/generic/base.py", line 68, in view
    return self.dispatch(request, *args, **kwargs)
  File "/Users/yi/.virtualenvs/yi3/lib/python3.6/site-packages/rest_framework/views.py", line 483, in dispatch
    response = self.handle_exception(exc)
  File "/Users/yi/.virtualenvs/yi3/lib/python3.6/site-packages/rest_framework/views.py", line 443, in handle_exception
    self.raise_uncaught_exception(exc)
  File "/Users/yi/.virtualenvs/yi3/lib/python3.6/site-packages/rest_framework/views.py", line 480, in dispatch
    response = handler(request, *args, **kwargs)
  File "/Users/yi/PycharmProjects/djangos/web_chat/chat/api_views/account.py", line 74, in post
    email_helper.send_captcha(receive_email=email)
  File "/Users/yi/PycharmProjects/djangos/web_chat/util/email.py", line 23, in send_captcha
    status = send_mail(email_title, email_body, self.email_from, [self.email_from, receive_email])
  File "/Users/yi/.virtualenvs/yi3/lib/python3.6/site-packages/django/core/mail/__init__.py", line 62, in send_mail
    return mail.send()
  File "/Users/yi/.virtualenvs/yi3/lib/python3.6/site-packages/django/core/mail/message.py", line 348, in send
    return self.get_connection(fail_silently).send_messages([self])
  File "/Users/yi/.virtualenvs/yi3/lib/python3.6/site-packages/django/core/mail/backends/smtp.py", line 111, in send_messages
    sent = self._send(message)
  File "/Users/yi/.virtualenvs/yi3/lib/python3.6/site-packages/django/core/mail/backends/smtp.py", line 127, in _send
    self.connection.sendmail(from_email, recipients, message.as_bytes(linesep='\r\n'))
  File "/usr/local/Cellar/python/3.6.5/Frameworks/Python.framework/Versions/3.6/lib/python3.6/smtplib.py", line 888, in sendmail
    raise SMTPDataError(code, resp)
smtplib.SMTPDataError: (554, b'DT:SPM 163 smtp14,EsCowABHCUBTRxtcZtX6Fw--.57059S2 1545291604,please see http://mail.163.com/help/help_spam_16.htm?ip=59.42.191.95&hostid=smtp14&time=1545291604')
[E 20181220 07:40:04 basehttp:124] "POST /api/v1/captcha/ HTTP/1.1" 500 16634
[E 20181220 07:41:05 exception:135] Internal Server Error: /api/v1/captcha/
Traceback (most recent call last):
  File "/Users/yi/.virtualenvs/yi3/lib/python3.6/site-packages/django/core/handlers/exception.py", line 41, in inner
    response = get_response(request)
  File "/Users/yi/.virtualenvs/yi3/lib/python3.6/site-packages/django/core/handlers/base.py", line 187, in _get_response
    response = self.process_exception_by_middleware(e, request)
  File "/Users/yi/.virtualenvs/yi3/lib/python3.6/site-packages/django/core/handlers/base.py", line 185, in _get_response
    response = wrapped_callback(request, *callback_args, **callback_kwargs)
  File "/Users/yi/.virtualenvs/yi3/lib/python3.6/site-packages/django/views/decorators/csrf.py", line 58, in wrapped_view
    return view_func(*args, **kwargs)
  File "/Users/yi/.virtualenvs/yi3/lib/python3.6/site-packages/django/views/generic/base.py", line 68, in view
    return self.dispatch(request, *args, **kwargs)
  File "/Users/yi/.virtualenvs/yi3/lib/python3.6/site-packages/rest_framework/views.py", line 483, in dispatch
    response = self.handle_exception(exc)
  File "/Users/yi/.virtualenvs/yi3/lib/python3.6/site-packages/rest_framework/views.py", line 443, in handle_exception
    self.raise_uncaught_exception(exc)
  File "/Users/yi/.virtualenvs/yi3/lib/python3.6/site-packages/rest_framework/views.py", line 480, in dispatch
    response = handler(request, *args, **kwargs)
  File "/Users/yi/PycharmProjects/djangos/web_chat/chat/api_views/account.py", line 74, in post
    email_helper.send_captcha(receive_email=email)
  File "/Users/yi/PycharmProjects/djangos/web_chat/util/email.py", line 25, in send_captcha
    status = send_mail(email_title, email_body, self.email_from, [self.email_from, receive_email])
  File "/Users/yi/.virtualenvs/yi3/lib/python3.6/site-packages/django/core/mail/__init__.py", line 62, in send_mail
    return mail.send()
  File "/Users/yi/.virtualenvs/yi3/lib/python3.6/site-packages/django/core/mail/message.py", line 348, in send
    return self.get_connection(fail_silently).send_messages([self])
  File "/Users/yi/.virtualenvs/yi3/lib/python3.6/site-packages/django/core/mail/backends/smtp.py", line 111, in send_messages
    sent = self._send(message)
  File "/Users/yi/.virtualenvs/yi3/lib/python3.6/site-packages/django/core/mail/backends/smtp.py", line 127, in _send
    self.connection.sendmail(from_email, recipients, message.as_bytes(linesep='\r\n'))
  File "/usr/local/Cellar/python/3.6.5/Frameworks/Python.framework/Versions/3.6/lib/python3.6/smtplib.py", line 888, in sendmail
    raise SMTPDataError(code, resp)
smtplib.SMTPDataError: (554, b'DT:SPM 163 smtp9,DcCowAAHY6mRRxtccp6RAA--.7325S2 1545291665,please see http://mail.163.com/help/help_spam_16.htm?ip=59.42.191.95&hostid=smtp9&time=1545291665')
[E 20181220 07:41:05 basehttp:124] "POST /api/v1/captcha/ HTTP/1.1" 500 16628
[I 20181220 07:42:10 basehttp:124] "POST /api/v1/captcha/ HTTP/1.1" 200 13
[I 20181220 08:54:33 basehttp:124] "POST /api/v1/captcha/ HTTP/1.1" 200 13
[I 20181220 08:55:36 basehttp:124] "POST /api/v1/captcha/ HTTP/1.1" 200 13
[I 20181220 08:57:12 basehttp:124] "POST /api/v1/captcha/ HTTP/1.1" 200 13
[I 20181220 09:01:04 basehttp:124] "POST /api/v1/captcha/ HTTP/1.1" 200 13
[I 20181220 09:06:36 basehttp:124] "POST /api/v1/captcha/ HTTP/1.1" 200 13
[I 20181220 09:08:50 basehttp:124] "POST /api/v1/captcha/ HTTP/1.1" 200 13
[I 20181220 09:10:33 basehttp:124] "POST /api/v1/captcha/ HTTP/1.1" 200 13
[I 20181220 13:28:11 basehttp:124] "GET /api/v1/test HTTP/1.1" 301 0
[I 20181220 13:28:11 basehttp:124] "GET /api/v1/test/ HTTP/1.1" 200 3
[I 20181220 13:42:42 basehttp:124] "GET /api/v1/test HTTP/1.1" 301 0
[I 20181220 13:42:42 basehttp:124] "GET /api/v1/test/ HTTP/1.1" 200 12
[I 20181220 13:44:26 basehttp:124] "GET /api/v1/test HTTP/1.1" 301 0
[I 20181220 13:44:26 basehttp:124] "GET /api/v1/test/ HTTP/1.1" 200 9
[I 20181220 13:44:27 basehttp:124] "GET /api/v1/test HTTP/1.1" 301 0
[I 20181220 13:44:27 basehttp:124] "GET /api/v1/test/ HTTP/1.1" 200 9
[I 20181220 13:45:20 basehttp:124] "GET /api/v1/test HTTP/1.1" 301 0
[I 20181220 13:45:20 basehttp:124] "GET /api/v1/test/ HTTP/1.1" 200 12
[I 20181220 13:52:58 basehttp:124] "GET /api/v1/test HTTP/1.1" 301 0
[E 20181220 13:52:58 exception:135] Internal Server Error: /api/v1/test/
Traceback (most recent call last):
  File "/Users/yi/.virtualenvs/yi3/lib/python3.6/site-packages/django/core/handlers/exception.py", line 41, in inner
    response = get_response(request)
  File "/Users/yi/.virtualenvs/yi3/lib/python3.6/site-packages/django/core/handlers/base.py", line 217, in _get_response
    response = self.process_exception_by_middleware(e, request)
  File "/Users/yi/.virtualenvs/yi3/lib/python3.6/site-packages/django/core/handlers/base.py", line 215, in _get_response
    response = response.render()
  File "/Users/yi/.virtualenvs/yi3/lib/python3.6/site-packages/django/template/response.py", line 107, in render
    self.content = self.rendered_content
  File "/Users/yi/.virtualenvs/yi3/lib/python3.6/site-packages/rest_framework/response.py", line 72, in rendered_content
    ret = renderer.render(self.data, accepted_media_type, context)
  File "/Users/yi/.virtualenvs/yi3/lib/python3.6/site-packages/rest_framework/renderers.py", line 105, in render
    allow_nan=not self.strict, separators=separators
  File "/Users/yi/.virtualenvs/yi3/lib/python3.6/site-packages/rest_framework/utils/json.py", line 28, in dumps
    return json.dumps(*args, **kwargs)
  File "/usr/local/Cellar/python/3.6.5/Frameworks/Python.framework/Versions/3.6/lib/python3.6/json/__init__.py", line 238, in dumps
    **kw).encode(obj)
  File "/usr/local/Cellar/python/3.6.5/Frameworks/Python.framework/Versions/3.6/lib/python3.6/json/encoder.py", line 199, in encode
    chunks = self.iterencode(o, _one_shot=True)
  File "/usr/local/Cellar/python/3.6.5/Frameworks/Python.framework/Versions/3.6/lib/python3.6/json/encoder.py", line 257, in iterencode
    return _iterencode(o, 0)
TypeError: keys must be a string
[E 20181220 13:52:58 basehttp:124] "GET /api/v1/test/ HTTP/1.1" 500 95141
[I 20181220 13:54:03 basehttp:124] "GET /api/v1/test HTTP/1.1" 301 0
[E 20181220 13:54:03 exception:135] Internal Server Error: /api/v1/test/
Traceback (most recent call last):
  File "/Users/yi/.virtualenvs/yi3/lib/python3.6/site-packages/django/core/handlers/exception.py", line 41, in inner
    response = get_response(request)
  File "/Users/yi/.virtualenvs/yi3/lib/python3.6/site-packages/django/core/handlers/base.py", line 217, in _get_response
    response = self.process_exception_by_middleware(e, request)
  File "/Users/yi/.virtualenvs/yi3/lib/python3.6/site-packages/django/core/handlers/base.py", line 215, in _get_response
    response = response.render()
  File "/Users/yi/.virtualenvs/yi3/lib/python3.6/site-packages/django/template/response.py", line 107, in render
    self.content = self.rendered_content
  File "/Users/yi/.virtualenvs/yi3/lib/python3.6/site-packages/rest_framework/response.py", line 72, in rendered_content
    ret = renderer.render(self.data, accepted_media_type, context)
  File "/Users/yi/.virtualenvs/yi3/lib/python3.6/site-packages/rest_framework/renderers.py", line 105, in render
    allow_nan=not self.strict, separators=separators
  File "/Users/yi/.virtualenvs/yi3/lib/python3.6/site-packages/rest_framework/utils/json.py", line 28, in dumps
    return json.dumps(*args, **kwargs)
  File "/usr/local/Cellar/python/3.6.5/Frameworks/Python.framework/Versions/3.6/lib/python3.6/json/__init__.py", line 238, in dumps
    **kw).encode(obj)
  File "/usr/local/Cellar/python/3.6.5/Frameworks/Python.framework/Versions/3.6/lib/python3.6/json/encoder.py", line 199, in encode
    chunks = self.iterencode(o, _one_shot=True)
  File "/usr/local/Cellar/python/3.6.5/Frameworks/Python.framework/Versions/3.6/lib/python3.6/json/encoder.py", line 257, in iterencode
    return _iterencode(o, 0)
TypeError: keys must be a string
[E 20181220 13:54:03 basehttp:124] "GET /api/v1/test/ HTTP/1.1" 500 95141
[I 20181220 14:06:27 basehttp:124] "GET /api/v1/test HTTP/1.1" 301 0
[I 20181220 14:06:27 basehttp:124] "GET /api/v1/test/ HTTP/1.1" 200 46
[I 20181220 14:06:29 basehttp:124] "GET /api/v1/test HTTP/1.1" 301 0
[I 20181220 14:06:29 basehttp:124] "GET /api/v1/test/ HTTP/1.1" 200 46
[I 20181220 14:06:29 basehttp:124] "GET /api/v1/test HTTP/1.1" 301 0
[I 20181220 14:06:29 basehttp:124] "GET /api/v1/test/ HTTP/1.1" 200 46
[I 20181220 14:07:51 basehttp:124] "GET /api/v1/test HTTP/1.1" 301 0
[I 20181220 14:07:51 basehttp:124] "GET /api/v1/test/ HTTP/1.1" 200 46
[E 20181220 14:09:20 exception:135] Internal Server Error: /api/v1/test
Traceback (most recent call last):
  File "/Users/yi/.virtualenvs/yi3/lib/python3.6/site-packages/django/core/handlers/exception.py", line 41, in inner
    response = get_response(request)
  File "/Users/yi/.virtualenvs/yi3/lib/python3.6/site-packages/django/utils/deprecation.py", line 138, in __call__
    response = self.process_request(request)
  File "/Users/yi/.virtualenvs/yi3/lib/python3.6/site-packages/django/middleware/common.py", line 63, in process_request
    path = self.get_full_path_with_slash(request)
  File "/Users/yi/.virtualenvs/yi3/lib/python3.6/site-packages/django/middleware/common.py", line 101, in get_full_path_with_slash
    'url': request.get_host() + new_path,
RuntimeError: You called this URL via POST, but the URL doesn't end in a slash and you have APPEND_SLASH set. Django can't redirect to the slash URL while maintaining POST data. Change your form to point to 127.0.0.1:8000/api/v1/test/ (note the trailing slash), or set APPEND_SLASH=False in your Django settings.
[E 20181220 14:09:20 basehttp:124] "POST /api/v1/test HTTP/1.1" 500 66036
[E 20181220 14:09:53 exception:135] Internal Server Error: /api/v1/test
Traceback (most recent call last):
  File "/Users/yi/.virtualenvs/yi3/lib/python3.6/site-packages/django/core/handlers/exception.py", line 41, in inner
    response = get_response(request)
  File "/Users/yi/.virtualenvs/yi3/lib/python3.6/site-packages/django/utils/deprecation.py", line 138, in __call__
    response = self.process_request(request)
  File "/Users/yi/.virtualenvs/yi3/lib/python3.6/site-packages/django/middleware/common.py", line 63, in process_request
    path = self.get_full_path_with_slash(request)
  File "/Users/yi/.virtualenvs/yi3/lib/python3.6/site-packages/django/middleware/common.py", line 101, in get_full_path_with_slash
    'url': request.get_host() + new_path,
RuntimeError: You called this URL via POST, but the URL doesn't end in a slash and you have APPEND_SLASH set. Django can't redirect to the slash URL while maintaining POST data. Change your form to point to 127.0.0.1:8000/api/v1/test/ (note the trailing slash), or set APPEND_SLASH=False in your Django settings.
[E 20181220 14:09:53 basehttp:124] "POST /api/v1/test HTTP/1.1" 500 66036
[E 20181220 14:10:28 exception:135] Internal Server Error: /api/v1/test
Traceback (most recent call last):
  File "/Users/yi/.virtualenvs/yi3/lib/python3.6/site-packages/django/core/handlers/exception.py", line 41, in inner
    response = get_response(request)
  File "/Users/yi/.virtualenvs/yi3/lib/python3.6/site-packages/django/utils/deprecation.py", line 138, in __call__
    response = self.process_request(request)
  File "/Users/yi/.virtualenvs/yi3/lib/python3.6/site-packages/django/middleware/common.py", line 63, in process_request
    path = self.get_full_path_with_slash(request)
  File "/Users/yi/.virtualenvs/yi3/lib/python3.6/site-packages/django/middleware/common.py", line 101, in get_full_path_with_slash
    'url': request.get_host() + new_path,
RuntimeError: You called this URL via POST, but the URL doesn't end in a slash and you have APPEND_SLASH set. Django can't redirect to the slash URL while maintaining POST data. Change your form to point to 127.0.0.1:8000/api/v1/test/ (note the trailing slash), or set APPEND_SLASH=False in your Django settings.
[E 20181220 14:10:28 basehttp:124] "POST /api/v1/test HTTP/1.1" 500 66036
[I 20181220 14:10:54 basehttp:124] "POST /api/v1/test/ HTTP/1.1" 200 2
[I 20181220 14:11:11 basehttp:124] "GET /api/v1/test/ HTTP/1.1" 200 55
[I 20181220 14:11:40 basehttp:124] "POST /api/v1/test/ HTTP/1.1" 200 2
[I 20181220 14:11:44 basehttp:124] "GET /api/v1/test/ HTTP/1.1" 200 54
[I 20181220 14:30:59 basehttp:124] "POST /api/v1/test/ HTTP/1.1" 200 2
[I 20181220 14:31:04 basehttp:124] "GET /api/v1/test/ HTTP/1.1" 200 58
[I 20181220 14:32:25 basehttp:124] "POST /api/v1/test/ HTTP/1.1" 200 2
[E 20181220 14:33:55 exception:135] Internal Server Error: /api/v1/test/
Traceback (most recent call last):
  File "/Users/yi/.virtualenvs/yi3/lib/python3.6/site-packages/django/core/handlers/exception.py", line 41, in inner
    response = get_response(request)
  File "/Users/yi/.virtualenvs/yi3/lib/python3.6/site-packages/django/core/handlers/base.py", line 187, in _get_response
    response = self.process_exception_by_middleware(e, request)
  File "/Users/yi/.virtualenvs/yi3/lib/python3.6/site-packages/django/core/handlers/base.py", line 185, in _get_response
    response = wrapped_callback(request, *callback_args, **callback_kwargs)
  File "/Users/yi/.virtualenvs/yi3/lib/python3.6/site-packages/django/views/decorators/csrf.py", line 58, in wrapped_view
    return view_func(*args, **kwargs)
  File "/Users/yi/.virtualenvs/yi3/lib/python3.6/site-packages/django/views/generic/base.py", line 68, in view
    return self.dispatch(request, *args, **kwargs)
  File "/Users/yi/.virtualenvs/yi3/lib/python3.6/site-packages/rest_framework/views.py", line 483, in dispatch
    response = self.handle_exception(exc)
  File "/Users/yi/.virtualenvs/yi3/lib/python3.6/site-packages/rest_framework/views.py", line 443, in handle_exception
    self.raise_uncaught_exception(exc)
  File "/Users/yi/.virtualenvs/yi3/lib/python3.6/site-packages/rest_framework/views.py", line 480, in dispatch
    response = handler(request, *args, **kwargs)
  File "/Users/yi/PycharmProjects/djangos/web_chat/chat/views.py", line 42, in post
    hash_key = 'test_hash_1_1' + i
TypeError: must be str, not int
[E 20181220 14:33:55 basehttp:124] "POST /api/v1/test/ HTTP/1.1" 500 15813
[I 20181220 14:34:25 basehttp:124] "POST /api/v1/test/ HTTP/1.1" 200 2
[I 20181220 14:37:59 basehttp:124] "POST /api/v1/test/ HTTP/1.1" 200 2
[I 20181220 14:39:16 basehttp:124] "POST /api/v1/test/ HTTP/1.1" 200 2
[E 20181220 14:41:22 exception:135] Internal Server Error: /api/v1/test/
Traceback (most recent call last):
  File "/Users/yi/.virtualenvs/yi3/lib/python3.6/site-packages/django/core/handlers/exception.py", line 41, in inner
    response = get_response(request)
  File "/Users/yi/.virtualenvs/yi3/lib/python3.6/site-packages/django/core/handlers/base.py", line 187, in _get_response
    response = self.process_exception_by_middleware(e, request)
  File "/Users/yi/.virtualenvs/yi3/lib/python3.6/site-packages/django/core/handlers/base.py", line 185, in _get_response
    response = wrapped_callback(request, *callback_args, **callback_kwargs)
  File "/Users/yi/.virtualenvs/yi3/lib/python3.6/site-packages/django/views/decorators/csrf.py", line 58, in wrapped_view
    return view_func(*args, **kwargs)
  File "/Users/yi/.virtualenvs/yi3/lib/python3.6/site-packages/django/views/generic/base.py", line 68, in view
    return self.dispatch(request, *args, **kwargs)
  File "/Users/yi/.virtualenvs/yi3/lib/python3.6/site-packages/rest_framework/views.py", line 483, in dispatch
    response = self.handle_exception(exc)
  File "/Users/yi/.virtualenvs/yi3/lib/python3.6/site-packages/rest_framework/views.py", line 443, in handle_exception
    self.raise_uncaught_exception(exc)
  File "/Users/yi/.virtualenvs/yi3/lib/python3.6/site-packages/rest_framework/views.py", line 480, in dispatch
    response = handler(request, *args, **kwargs)
  File "/Users/yi/PycharmProjects/djangos/web_chat/chat/views.py", line 42, in post
    d = {'love': '多对多', 'age': 111, 1: l}
UnboundLocalError: local variable 'l' referenced before assignment
[E 20181220 14:41:22 basehttp:124] "POST /api/v1/test/ HTTP/1.1" 500 15892
[I 20181220 14:41:50 basehttp:124] "POST /api/v1/test/ HTTP/1.1" 200 2
[I 20181220 14:41:51 basehttp:124] "POST /api/v1/test/ HTTP/1.1" 200 2
[I 20181220 14:42:38 basehttp:124] "POST /api/v1/test/ HTTP/1.1" 200 2
[I 20181220 14:43:09 basehttp:124] "POST /api/v1/test/ HTTP/1.1" 200 2
[I 20181220 14:49:21 basehttp:124] "GET /api/v1/test/ HTTP/1.1" 200 220
[E 20181220 14:50:50 exception:135] Internal Server Error: /api/v1/test/
Traceback (most recent call last):
  File "/Users/yi/.virtualenvs/yi3/lib/python3.6/site-packages/django/core/handlers/exception.py", line 41, in inner
    response = get_response(request)
  File "/Users/yi/.virtualenvs/yi3/lib/python3.6/site-packages/django/core/handlers/base.py", line 187, in _get_response
    response = self.process_exception_by_middleware(e, request)
  File "/Users/yi/.virtualenvs/yi3/lib/python3.6/site-packages/django/core/handlers/base.py", line 185, in _get_response
    response = wrapped_callback(request, *callback_args, **callback_kwargs)
  File "/Users/yi/.virtualenvs/yi3/lib/python3.6/site-packages/django/views/decorators/csrf.py", line 58, in wrapped_view
    return view_func(*args, **kwargs)
  File "/Users/yi/.virtualenvs/yi3/lib/python3.6/site-packages/django/views/generic/base.py", line 68, in view
    return self.dispatch(request, *args, **kwargs)
  File "/Users/yi/.virtualenvs/yi3/lib/python3.6/site-packages/rest_framework/views.py", line 483, in dispatch
    response = self.handle_exception(exc)
  File "/Users/yi/.virtualenvs/yi3/lib/python3.6/site-packages/rest_framework/views.py", line 443, in handle_exception
    self.raise_uncaught_exception(exc)
  File "/Users/yi/.virtualenvs/yi3/lib/python3.6/site-packages/rest_framework/views.py", line 480, in dispatch
    response = handler(request, *args, **kwargs)
  File "/Users/yi/PycharmProjects/djangos/web_chat/chat/views.py", line 42, in get
    print(type(res['l']))
KeyError: 'l'
[E 20181220 14:50:50 basehttp:124] "GET /api/v1/test/ HTTP/1.1" 500 15642
[E 20181220 14:50:51 exception:135] Internal Server Error: /api/v1/test/
Traceback (most recent call last):
  File "/Users/yi/.virtualenvs/yi3/lib/python3.6/site-packages/django/core/handlers/exception.py", line 41, in inner
    response = get_response(request)
  File "/Users/yi/.virtualenvs/yi3/lib/python3.6/site-packages/django/core/handlers/base.py", line 187, in _get_response
    response = self.process_exception_by_middleware(e, request)
  File "/Users/yi/.virtualenvs/yi3/lib/python3.6/site-packages/django/core/handlers/base.py", line 185, in _get_response
    response = wrapped_callback(request, *callback_args, **callback_kwargs)
  File "/Users/yi/.virtualenvs/yi3/lib/python3.6/site-packages/django/views/decorators/csrf.py", line 58, in wrapped_view
    return view_func(*args, **kwargs)
  File "/Users/yi/.virtualenvs/yi3/lib/python3.6/site-packages/django/views/generic/base.py", line 68, in view
    return self.dispatch(request, *args, **kwargs)
  File "/Users/yi/.virtualenvs/yi3/lib/python3.6/site-packages/rest_framework/views.py", line 483, in dispatch
    response = self.handle_exception(exc)
  File "/Users/yi/.virtualenvs/yi3/lib/python3.6/site-packages/rest_framework/views.py", line 443, in handle_exception
    self.raise_uncaught_exception(exc)
  File "/Users/yi/.virtualenvs/yi3/lib/python3.6/site-packages/rest_framework/views.py", line 480, in dispatch
    response = handler(request, *args, **kwargs)
  File "/Users/yi/PycharmProjects/djangos/web_chat/chat/views.py", line 42, in get
    print(type(res['l']))
KeyError: 'l'
[E 20181220 14:50:51 basehttp:124] "GET /api/v1/test/ HTTP/1.1" 500 15642
[I 20181220 14:51:05 basehttp:124] "GET /api/v1/test/ HTTP/1.1" 200 220
[I 20181220 14:52:08 basehttp:124] "POST /api/v1/test/ HTTP/1.1" 200 2
[I 20181220 14:52:12 basehttp:124] "GET /api/v1/test/ HTTP/1.1" 200 243
[I 20181220 14:52:54 basehttp:124] "GET /api/v1/test/ HTTP/1.1" 200 243
[I 20181220 14:54:47 basehttp:124] "GET /api/v1/test/ HTTP/1.1" 200 18
[E 20181220 14:56:46 exception:135] Internal Server Error: /api/v1/test/
Traceback (most recent call last):
  File "/Users/yi/.virtualenvs/yi3/lib/python3.6/site-packages/django/core/handlers/exception.py", line 41, in inner
    response = get_response(request)
  File "/Users/yi/.virtualenvs/yi3/lib/python3.6/site-packages/django/core/handlers/base.py", line 187, in _get_response
    response = self.process_exception_by_middleware(e, request)
  File "/Users/yi/.virtualenvs/yi3/lib/python3.6/site-packages/django/core/handlers/base.py", line 185, in _get_response
    response = wrapped_callback(request, *callback_args, **callback_kwargs)
  File "/Users/yi/.virtualenvs/yi3/lib/python3.6/site-packages/django/views/decorators/csrf.py", line 58, in wrapped_view
    return view_func(*args, **kwargs)
  File "/Users/yi/.virtualenvs/yi3/lib/python3.6/site-packages/django/views/generic/base.py", line 68, in view
    return self.dispatch(request, *args, **kwargs)
  File "/Users/yi/.virtualenvs/yi3/lib/python3.6/site-packages/rest_framework/views.py", line 483, in dispatch
    response = self.handle_exception(exc)
  File "/Users/yi/.virtualenvs/yi3/lib/python3.6/site-packages/rest_framework/views.py", line 443, in handle_exception
    self.raise_uncaught_exception(exc)
  File "/Users/yi/.virtualenvs/yi3/lib/python3.6/site-packages/rest_framework/views.py", line 480, in dispatch
    response = handler(request, *args, **kwargs)
  File "/Users/yi/PycharmProjects/djangos/web_chat/chat/views.py", line 51, in post
    self.conn.hmset(hash_key, 'd', '呜呜呜呜呜呜呜')
TypeError: hmset() takes 3 positional arguments but 4 were given
[E 20181220 14:56:46 basehttp:124] "POST /api/v1/test/ HTTP/1.1" 500 15900
[E 20181220 14:56:47 exception:135] Internal Server Error: /api/v1/test/
Traceback (most recent call last):
  File "/Users/yi/.virtualenvs/yi3/lib/python3.6/site-packages/django/core/handlers/exception.py", line 41, in inner
    response = get_response(request)
  File "/Users/yi/.virtualenvs/yi3/lib/python3.6/site-packages/django/core/handlers/base.py", line 187, in _get_response
    response = self.process_exception_by_middleware(e, request)
  File "/Users/yi/.virtualenvs/yi3/lib/python3.6/site-packages/django/core/handlers/base.py", line 185, in _get_response
    response = wrapped_callback(request, *callback_args, **callback_kwargs)
  File "/Users/yi/.virtualenvs/yi3/lib/python3.6/site-packages/django/views/decorators/csrf.py", line 58, in wrapped_view
    return view_func(*args, **kwargs)
  File "/Users/yi/.virtualenvs/yi3/lib/python3.6/site-packages/django/views/generic/base.py", line 68, in view
    return self.dispatch(request, *args, **kwargs)
  File "/Users/yi/.virtualenvs/yi3/lib/python3.6/site-packages/rest_framework/views.py", line 483, in dispatch
    response = self.handle_exception(exc)
  File "/Users/yi/.virtualenvs/yi3/lib/python3.6/site-packages/rest_framework/views.py", line 443, in handle_exception
    self.raise_uncaught_exception(exc)
  File "/Users/yi/.virtualenvs/yi3/lib/python3.6/site-packages/rest_framework/views.py", line 480, in dispatch
    response = handler(request, *args, **kwargs)
  File "/Users/yi/PycharmProjects/djangos/web_chat/chat/views.py", line 51, in post
    self.conn.hmset(hash_key, 'd', '呜呜呜呜呜呜呜')
TypeError: hmset() takes 3 positional arguments but 4 were given
[E 20181220 14:56:47 basehttp:124] "POST /api/v1/test/ HTTP/1.1" 500 15900
[I 20181220 14:57:03 basehttp:124] "POST /api/v1/test/ HTTP/1.1" 200 2
[I 20181220 14:57:12 basehttp:124] "GET /api/v1/test/ HTTP/1.1" 200 23
[I 20181220 15:25:51 basehttp:124] "GET /api/v1/test/ HTTP/1.1" 200 2
[I 20181220 16:00:59 basehttp:124] "GET /api/v1/test/ HTTP/1.1" 200 13
[I 20181220 16:01:11 basehttp:124] "GET /api/v1/test/ HTTP/1.1" 200 13
[I 20181220 16:01:15 basehttp:124] "GET /api/v1/test/ HTTP/1.1" 200 13
[I 20181220 16:02:39 basehttp:124] "GET /api/v1/test/ HTTP/1.1" 200 39
[I 20181220 16:02:39 basehttp:124] "POST /api/v1/test/ HTTP/1.1" 200 2
[I 20181220 16:02:52 basehttp:124] "POST /api/v1/test/ HTTP/1.1" 200 2
[I 20181220 16:02:52 basehttp:124] "GET /api/v1/test/ HTTP/1.1" 200 39
[I 20181220 16:05:42 basehttp:124] "GET /api/v1/test2/ HTTP/1.1" 200 2
[I 20181220 16:05:49 basehttp:124] "GET /api/v1/test/ HTTP/1.1" 200 13
[I 20181220 16:05:54 basehttp:124] "GET /api/v1/test2/ HTTP/1.1" 200 2
[I 20181220 16:06:02 basehttp:124] "GET /api/v1/test/ HTTP/1.1" 200 13
[E 20181220 16:06:16 exception:135] Internal Server Error: /api/v1/test2/
Traceback (most recent call last):
  File "/Users/yi/.virtualenvs/yi3/lib/python3.6/site-packages/django/core/handlers/exception.py", line 41, in inner
    response = get_response(request)
  File "/Users/yi/.virtualenvs/yi3/lib/python3.6/site-packages/django/core/handlers/base.py", line 187, in _get_response
    response = self.process_exception_by_middleware(e, request)
  File "/Users/yi/.virtualenvs/yi3/lib/python3.6/site-packages/django/core/handlers/base.py", line 185, in _get_response
    response = wrapped_callback(request, *callback_args, **callback_kwargs)
  File "/Users/yi/.virtualenvs/yi3/lib/python3.6/site-packages/django/views/decorators/csrf.py", line 58, in wrapped_view
    return view_func(*args, **kwargs)
  File "/Users/yi/.virtualenvs/yi3/lib/python3.6/site-packages/django/views/generic/base.py", line 68, in view
    return self.dispatch(request, *args, **kwargs)
  File "/Users/yi/.virtualenvs/yi3/lib/python3.6/site-packages/rest_framework/views.py", line 483, in dispatch
    response = self.handle_exception(exc)
  File "/Users/yi/.virtualenvs/yi3/lib/python3.6/site-packages/rest_framework/views.py", line 443, in handle_exception
    self.raise_uncaught_exception(exc)
  File "/Users/yi/.virtualenvs/yi3/lib/python3.6/site-packages/rest_framework/views.py", line 480, in dispatch
    response = handler(request, *args, **kwargs)
  File "/Users/yi/PycharmProjects/djangos/web_chat/chat/views.py", line 57, in post
    a = self.conn.hset('666', 'test')
TypeError: hset() missing 1 required positional argument: 'value'
[E 20181220 16:06:16 basehttp:124] "POST /api/v1/test2/ HTTP/1.1" 500 15884
[I 20181220 16:06:24 basehttp:124] "GET /api/v1/test/ HTTP/1.1" 200 13
[I 20181220 16:06:31 basehttp:124] "POST /api/v1/test2/ HTTP/1.1" 200 11
[I 20181220 16:06:39 basehttp:124] "GET /api/v1/test/ HTTP/1.1" 200 13
[I 20181220 16:06:58 basehttp:124] "GET /api/v1/test/ HTTP/1.1" 200 39
[I 20181220 16:06:58 basehttp:124] "POST /api/v1/test/ HTTP/1.1" 200 2
